Workbook

Sheet PANEL MENSUAL
A2: MES A EVALUAR | B2: OCTUBRE | D2: AÑO | E2: ='ESTADO CONTABLE'!B2 -> 2026
A4: MENSUALIDADES ESPERADAS | B4: =COUNTIF(F15:F150,"COBRADA")+COUNTIF(F15:F150,"ABONO")+COUNTIF(F15:F150,"PENDIENTE") -> 78 | C4: MENSUALIDADES COBRADAS | D4: =COUNTIF(F15:F150,"COBRADA") -> 70 | E4: MENSUALIDADES FALTANTES | F4: =COUNTIF(F15:F150,"PENDIENTE")+COUNTIF(F15:F150,"ABONO") -> 8
A7: INGRESO ESPERADO NETO (SIN IVA) | B7: =SUM(C15:C150) -> 58275.862 | C7: INGRESO REGISTRADO BRUTO | D7: {=_xlfn.XLOOKUP($B$2,'ESTADO CONTABLE'!$A$5:$A$16,'ESTADO CONTABLE'!$B$5:$B$16,0)} -> 66356 | E7: INGRESO NETO (IVA DIGITAL) | F7: {=_xlfn.XLOOKUP($B$2,'ESTADO CONTABLE'!$A$5:$A$16,'ESTADO CONTABLE'!$J$5:$J$16,0)} -> 61045.655
A9: EGRESOS DEL MES | B9: {=_xlfn.XLOOKUP($B$2,'ESTADO CONTABLE'!$A$5:$A$16,'ESTADO CONTABLE'!$K$5:$K$16,0)} -> 35596.97 | C9: UTILIDAD REAL | D9: {=_xlfn.XLOOKUP($B$2,'ESTADO CONTABLE'!$A$5:$A$16,'ESTADO CONTABLE'!$L$5:$L$16,0)} -> 25448.685 | E9: GASTOS FIJOS PRESUP. | F9: {=_xlfn.XLOOKUP($B$2,'ESTADO CONTABLE'!$A$5:$A$16,'ESTADO CONTABLE'!$M$5:$M$16,0)} -> 43926
A11: RESULTADO ACTUAL VS FIJOS | B11: {=_xlfn.XLOOKUP($B$2,'ESTADO CONTABLE'!$A$5:$A$16,'ESTADO CONTABLE'!$N$5:$N$16,0)} -> 17119.655 | E11: RESULTADO PRESUPUESTADO | F11: =B7-F9 -> 14349.862
A13: DETALLE DE MENSUALIDADES DEL MES SELECCIONADO
A14: ALUMNA | B14: GRUPO | C14: MENSUALIDAD ESPERADA NETA (BONIFICACIÓN E IVA) | D14: PAGO REGISTRADO | E14: MÉTODO | F14: ESTATUS | G14: COBRAR DESDE
A15: {=IFERROR(INDEX('BASE DE DATOSS'!A:A,ROW()-13),"")} -> AMEYALI MARTÍNEZ I. MORALES | B15: {=IF(A15="","",IFERROR(INDEX('BASE DE DATOSS'!C:C,ROW()-13),""))} -> KIDS 3 | C15: {=IF(A15="","",LET(mes,DATE($E$2,MATCH($B$2,'ESTADO CONTABLE'!$A$5:$A$16,0),1),cobrarDesde,IFERROR(INDEX('BASE DE DATOSS'!I:I,ROW()-13),""),pausada,SUMPRODUCT((UPPER(TRIM('PAUSAS MENSUALIDADES'!$A$5:$A$500))=UPPER(TRIM(A15)))*('PAUSAS MENSUALIDADES'!$B$5:$B$500=mes)*(UPPER(TRIM('PAUSAS MENSUALIDADES'!$D$5:$D$500))="APLICAR"))>0,IF(OR(AND(cobrarDesde<>"",mes<cobrarDesde),pausada),0,MAX(IFNA(VLOOKUP(B15,COSTOS!$A$3:$B$13,2,FALSE),0)-150,0)/1.16)))} -> 689.65517 | D15: {=IF(A15="","",LET(mes,DATE($E$2,MATCH($B$2,'ESTADO CONTABLE'!$A$5:$A$16,0),1),abonos,SUMIFS('ABONOS MENSUALIDADES'!$F$5:$F$500,'ABONOS MENSUALIDADES'!$C$5:$C$500,A15,'ABONOS MENSUALIDADES'!$D$5:$D$500,mes),pago,CHOOSE(MATCH($B$2,'ESTADO CONTABLE'!$A$5:$A$16,0),IFNA(_xlfn.XLOOKUP(A15,PAGOS!$A$2:$A$996,PAGOS!$E$2:$E$996,""),""),IFNA(_xlfn.XLOOKUP(A15,PAGOS!$A$2:$A$996,PAGOS!$G$2:$G$996,""),""),IFNA(_xlfn.XLOOKUP(A15,PAGOS!$A$2:$A$996,PAGOS!$J$2:$J$996,""),""),IFNA(_xlfn.XLOOKUP(A15,PAGOS!$A$2:$A$996,PAGOS!$M$2:$M$996,""),""),IFNA(_xlfn.XLOOKUP(A15,PAGOS!$A$2:$A$996,PAGOS!$P$2:$P$996,""),""),IFNA(_xlfn.XLOOKUP(A15,PAGOS!$A$2:$A$996,PAGOS!$S$2:$S$996,""),""),IFNA(_xlfn.XLOOKUP(A15,PAGOS!$A$2:$A$996,PAGOS!$V$2:$V$996,""),""),IFNA(_xlfn.XLOOKUP(A15,PAGOS!$A$2:$A$996,PAGOS!$Y$2:$Y$996,""),""),IFNA(_xlfn.XLOOKUP(A15,PAGOS!$A$2:$A$996,PAGOS!$AB$2:$AB$996,""),""),IFNA(_xlfn.XLOOKUP(A15,PAGOS!$A$2:$A$996,PAGOS!$AE$2:$AE$996,""),""),IFNA(_xlfn.XLOOKUP(A15,PAGOS!$A$2:$A$996,PAGOS!$AH$2:$AH$996,""),""),IFNA(_xlfn.XLOOKUP(A15,PAGOS!$A$2:$A$996,PAGOS!$AK$2:$AK$996,""),"")),IF(abonos>0,abonos,pago)))} -> 400 | E15: =IFERROR(__xludf.DUMMYFUNCTION("IF(A15="""","""",LET(mes,DATE($E$2,MATCH($B$2,'ESTADO CONTABLE'!$A$5:$A$16,0),1),abonos,SUMIFS('ABONOS MENSUALIDADES'!$F$5:$F$500,'ABONOS MENSUALIDADES'!$C$5:$C$500,A15,'ABONOS MENSUALIDADES'!$D$5:$D$500,mes),metodoDirecto,CHOOSE(MATCH($B$2,'ESTADO CONTAB"&"LE'!$A$5:$A$16,0),IF(ISNUMBER(D15),""POR CLASIFICAR"",""""),IFNA(XLOOKUP(A15,PAGOS!$A$2:$A$996,PAGOS!$H$2:$H$996,""""),""""),IFNA(XLOOKUP(A15,PAGOS!$A$2:$A$996,PAGOS!$K$2:$K$996,""""),""""),IFNA(XLOOKUP(A15,PAGOS!$A$2:$A$996,PAGOS!$N$2:$N$996,""""),""""),"&"IFNA(XLOOKUP(A15,PAGOS!$A$2:$A$996,PAGOS!$Q$2:$Q$996,""""),""""),IFNA(XLOOKUP(A15,PAGOS!$A$2:$A$996,PAGOS!$T$2:$T$996,""""),""""),IFNA(XLOOKUP(A15,PAGOS!$A$2:$A$996,PAGOS!$W$2:$W$996,""""),""""),IFNA(XLOOKUP(A15,PAGOS!$A$2:$A$996,PAGOS!$Z$2:$Z$996,""""),"&"""""),IFNA(XLOOKUP(A15,PAGOS!$A$2:$A$996,PAGOS!$AC$2:$AC$996,""""),""""),IFNA(XLOOKUP(A15,PAGOS!$A$2:$A$996,PAGOS!$AF$2:$AF$996,""""),""""),IFNA(XLOOKUP(A15,PAGOS!$A$2:$A$996,PAGOS!$AI$2:$AI$996,""""),""""),IFNA(XLOOKUP(A15,PAGOS!$A$2:$A$996,PAGOS!$AL$2:$"&"AL$996,""""),"""")),IF(abonos>0,IFERROR(TEXTJOIN("" + "",TRUE,UNIQUE(FILTER('ABONOS MENSUALIDADES'!$E$5:$E$500,'ABONOS MENSUALIDADES'!$C$5:$C$500=A15,'ABONOS MENSUALIDADES'!$D$5:$D$500=mes))),""""),metodoDirecto)))"),"TRANSFERENCIA") -> TRANSFERENCIA | F15: {=IF(A15="","",LET(mes,DATE($E$2,MATCH($B$2,'ESTADO CONTABLE'!$A$5:$A$16,0),1),cobrarDesde,IFERROR(INDEX('BASE DE DATOSS'!I:I,ROW()-13),""),pausada,SUMPRODUCT((UPPER(TRIM('PAUSAS MENSUALIDADES'!$A$5:$A$500))=UPPER(TRIM(A15)))*('PAUSAS MENSUALIDADES'!$B$5:$B$500=mes)*(UPPER(TRIM('PAUSAS MENSUALIDADES'!$D$5:$D$500))="APLICAR"))>0,abonoActivo,SUMIFS('ABONOS MENSUALIDADES'!$F$5:$F$500,'ABONOS MENSUALIDADES'!$C$5:$C$500,A15,'ABONOS MENSUALIDADES'!$D$5:$D$500,mes,'ABONOS MENSUALIDADES'!$G$5:$G$500,"<>*CONSOLIDADO EN PAGOS*")>0,esperadaBruta,MAX(IFNA(VLOOKUP(B15,COSTOS!$A$3:$B$13,2,FALSE),0)-150,0),IF(AND(cobrarDesde<>"",mes<cobrarDesde),"AÚN NO INICIA",IF(pausada,"PAUSADA",IF(AND(abonoActivo,COUNTIFS('ABONOS MENSUALIDADES'!$C$5:$C$500,A15,'ABONOS MENSUALIDADES'!$D$5:$D$500,mes,'ABONOS MENSUALIDADES'!$G$5:$G$500,"*MENSUALIDAD LIQUIDADA*")=0),"ABONO",IF(N(D15)>=esperadaBruta,"COBRADA",IF(N(D15)>0,"ABONO","PENDIENTE")))))))} -> ABONO | G15: {=IF(A15="","",IFERROR(INDEX('BASE DE DATOSS'!I:I,ROW()-13),""))} -> 46023
A16: {=IFERROR(INDEX('BASE DE DATOSS'!A:A,ROW()-13),"")} -> ANA PAULA GUTIERREZ MENESES | B16: {=IF(A16="","",IFERROR(INDEX('BASE DE DATOSS'!C:C,ROW()-13),""))} -> KIDS 3 | C16: {=IF(A16="","",LET(mes,DATE($E$2,MATCH($B$2,'ESTADO CONTABLE'!$A$5:$A$16,0),1),cobrarDesde,IFERROR(INDEX('BASE DE DATOSS'!I:I,ROW()-13),""),pausada,SUMPRODUCT((UPPER(TRIM('PAUSAS MENSUALIDADES'!$A$5:$A$500))=UPPER(TRIM(A16)))*('PAUSAS MENSUALIDADES'!$B$5:$B$500=mes)*(UPPER(TRIM('PAUSAS MENSUALIDADES'!$D$5:$D$500))="APLICAR"))>0,IF(OR(AND(cobrarDesde<>"",mes<cobrarDesde),pausada),0,MAX(IFNA(VLOOKUP(B16,COSTOS!$A$3:$B$13,2,FALSE),0)-150,0)/1.16)))} -> 689.65517 | D16: {=IF(A16="","",LET(mes,DATE($E$2,MATCH($B$2,'ESTADO CONTABLE'!$A$5:$A$16,0),1),abonos,SUMIFS('ABONOS MENSUALIDADES'!$F$5:$F$500,'ABONOS MENSUALIDADES'!$C$5:$C$500,A16,'ABONOS MENSUALIDADES'!$D$5:$D$500,mes),pago,CHOOSE(MATCH($B$2,'ESTADO CONTABLE'!$A$5:$A$16,0),IFNA(_xlfn.XLOOKUP(A16,PAGOS!$A$2:$A$996,PAGOS!$E$2:$E$996,""),""),IFNA(_xlfn.XLOOKUP(A16,PAGOS!$A$2:$A$996,PAGOS!$G$2:$G$996,""),""),IFNA(_xlfn.XLOOKUP(A16,PAGOS!$A$2:$A$996,PAGOS!$J$2:$J$996,""),""),IFNA(_xlfn.XLOOKUP(A16,PAGOS!$A$2:$A$996,PAGOS!$M$2:$M$996,""),""),IFNA(_xlfn.XLOOKUP(A16,PAGOS!$A$2:$A$996,PAGOS!$P$2:$P$996,""),""),IFNA(_xlfn.XLOOKUP(A16,PAGOS!$A$2:$A$996,PAGOS!$S$2:$S$996,""),""),IFNA(_xlfn.XLOOKUP(A16,PAGOS!$A$2:$A$996,PAGOS!$V$2:$V$996,""),""),IFNA(_xlfn.XLOOKUP(A16,PAGOS!$A$2:$A$996,PAGOS!$Y$2:$Y$996,""),""),IFNA(_xlfn.XLOOKUP(A16,PAGOS!$A$2:$A$996,PAGOS!$AB$2:$AB$996,""),""),IFNA(_xlfn.XLOOKUP(A16,PAGOS!$A$2:$A$996,PAGOS!$AE$2:$AE$996,""),""),IFNA(_xlfn.XLOOKUP(A16,PAGOS!$A$2:$A$996,PAGOS!$AH$2:$AH$996,""),""),IFNA(_xlfn.XLOOKUP(A16,PAGOS!$A$2:$A$996,PAGOS!$AK$2:$AK$996,""),"")),IF(abonos>0,abonos,pago)))} -> 800 | E16: =IFERROR(__xludf.DUMMYFUNCTION("IF(A16="""","""",LET(mes,DATE($E$2,MATCH($B$2,'ESTADO CONTABLE'!$A$5:$A$16,0),1),abonos,SUMIFS('ABONOS MENSUALIDADES'!$F$5:$F$500,'ABONOS MENSUALIDADES'!$C$5:$C$500,A16,'ABONOS MENSUALIDADES'!$D$5:$D$500,mes),metodoDirecto,CHOOSE(MATCH($B$2,'ESTADO CONTAB"&"LE'!$A$5:$A$16,0),IF(ISNUMBER(D16),""POR CLASIFICAR"",""""),IFNA(XLOOKUP(A16,PAGOS!$A$2:$A$996,PAGOS!$H$2:$H$996,""""),""""),IFNA(XLOOKUP(A16,PAGOS!$A$2:$A$996,PAGOS!$K$2:$K$996,""""),""""),IFNA(XLOOKUP(A16,PAGOS!$A$2:$A$996,PAGOS!$N$2:$N$996,""""),""""),"&"IFNA(XLOOKUP(A16,PAGOS!$A$2:$A$996,PAGOS!$Q$2:$Q$996,""""),""""),IFNA(XLOOKUP(A16,PAGOS!$A$2:$A$996,PAGOS!$T$2:$T$996,""""),""""),IFNA(XLOOKUP(A16,PAGOS!$A$2:$A$996,PAGOS!$W$2:$W$996,""""),""""),IFNA(XLOOKUP(A16,PAGOS!$A$2:$A$996,PAGOS!$Z$2:$Z$996,""""),"&"""""),IFNA(XLOOKUP(A16,PAGOS!$A$2:$A$996,PAGOS!$AC$2:$AC$996,""""),""""),IFNA(XLOOKUP(A16,PAGOS!$A$2:$A$996,PAGOS!$AF$2:$AF$996,""""),""""),IFNA(XLOOKUP(A16,PAGOS!$A$2:$A$996,PAGOS!$AI$2:$AI$996,""""),""""),IFNA(XLOOKUP(A16,PAGOS!$A$2:$A$996,PAGOS!$AL$2:$"&"AL$996,""""),"""")),IF(abonos>0,IFERROR(TEXTJOIN("" + "",TRUE,UNIQUE(FILTER('ABONOS MENSUALIDADES'!$E$5:$E$500,'ABONOS MENSUALIDADES'!$C$5:$C$500=A16,'ABONOS MENSUALIDADES'!$D$5:$D$500=mes))),""""),metodoDirecto)))"),"TRANSFERENCIA") -> TRANSFERENCIA | F16: {=IF(A16="","",LET(mes,DATE($E$2,MATCH($B$2,'ESTADO CONTABLE'!$A$5:$A$16,0),1),cobrarDesde,IFERROR(INDEX('BASE DE DATOSS'!I:I,ROW()-13),""),pausada,SUMPRODUCT((UPPER(TRIM('PAUSAS MENSUALIDADES'!$A$5:$A$500))=UPPER(TRIM(A16)))*('PAUSAS MENSUALIDADES'!$B$5:$B$500=mes)*(UPPER(TRIM('PAUSAS MENSUALIDADES'!$D$5:$D$500))="APLICAR"))>0,abonoActivo,SUMIFS('ABONOS MENSUALIDADES'!$F$5:$F$500,'ABONOS MENSUALIDADES'!$C$5:$C$500,A16,'ABONOS MENSUALIDADES'!$D$5:$D$500,mes,'ABONOS MENSUALIDADES'!$G$5:$G$500,"<>*CONSOLIDADO EN PAGOS*")>0,esperadaBruta,MAX(IFNA(VLOOKUP(B16,COSTOS!$A$3:$B$13,2,FALSE),0)-150,0),IF(AND(cobrarDesde<>"",mes<cobrarDesde),"AÚN NO INICIA",IF(pausada,"PAUSADA",IF(AND(abonoActivo,COUNTIFS('ABONOS MENSUALIDADES'!$C$5:$C$500,A16,'ABONOS MENSUALIDADES'!$D$5:$D$500,mes,'ABONOS MENSUALIDADES'!$G$5:$G$500,"*MENSUALIDAD LIQUIDADA*")=0),"ABONO",IF(N(D16)>=esperadaBruta,"COBRADA",IF(N(D16)>0,"ABONO","PENDIENTE")))))))} -> COBRADA | G16: {=IF(A16="","",IFERROR(INDEX('BASE DE DATOSS'!I:I,ROW()-13),""))} -> 46023
A17: {=IFERROR(INDEX('BASE DE DATOSS'!A:A,ROW()-13),"")} -> ANA VICTORIA REVUELTA LARA | B17: {=IF(A17="","",IFERROR(INDEX('BASE DE DATOSS'!C:C,ROW()-13),""))} -> JR 2 | C17: {=IF(A17="","",LET(mes,DATE($E$2,MATCH($B$2,'ESTADO CONTABLE'!$A$5:$A$16,0),1),cobrarDesde,IFERROR(INDEX('BASE DE DATOSS'!I:I,ROW()-13),""),pausada,SUMPRODUCT((UPPER(TRIM('PAUSAS MENSUALIDADES'!$A$5:$A$500))=UPPER(TRIM(A17)))*('PAUSAS MENSUALIDADES'!$B$5:$B$500=mes)*(UPPER(TRIM('PAUSAS MENSUALIDADES'!$D$5:$D$500))="APLICAR"))>0,IF(OR(AND(cobrarDesde<>"",mes<cobrarDesde),pausada),0,MAX(IFNA(VLOOKUP(B17,COSTOS!$A$3:$B$13,2,FALSE),0)-150,0)/1.16)))} -> 689.65517 | D17: {=IF(A17="","",LET(mes,DATE($E$2,MATCH($B$2,'ESTADO CONTABLE'!$A$5:$A$16,0),1),abonos,SUMIFS('ABONOS MENSUALIDADES'!$F$5:$F$500,'ABONOS MENSUALIDADES'!$C$5:$C$500,A17,'ABONOS MENSUALIDADES'!$D$5:$D$500,mes),pago,CHOOSE(MATCH($B$2,'ESTADO CONTABLE'!$A$5:$A$16,0),IFNA(_xlfn.XLOOKUP(A17,PAGOS!$A$2:$A$996,PAGOS!$E$2:$E$996,""),""),IFNA(_xlfn.XLOOKUP(A17,PAGOS!$A$2:$A$996,PAGOS!$G$2:$G$996,""),""),IFNA(_xlfn.XLOOKUP(A17,PAGOS!$A$2:$A$996,PAGOS!$J$2:$J$996,""),""),IFNA(_xlfn.XLOOKUP(A17,PAGOS!$A$2:$A$996,PAGOS!$M$2:$M$996,""),""),IFNA(_xlfn.XLOOKUP(A17,PAGOS!$A$2:$A$996,PAGOS!$P$2:$P$996,""),""),IFNA(_xlfn.XLOOKUP(A17,PAGOS!$A$2:$A$996,PAGOS!$S$2:$S$996,""),""),IFNA(_xlfn.XLOOKUP(A17,PAGOS!$A$2:$A$996,PAGOS!$V$2:$V$996,""),""),IFNA(_xlfn.XLOOKUP(A17,PAGOS!$A$2:$A$996,PAGOS!$Y$2:$Y$996,""),""),IFNA(_xlfn.XLOOKUP(A17,PAGOS!$A$2:$A$996,PAGOS!$AB$2:$AB$996,""),""),IFNA(_xlfn.XLOOKUP(A17,PAGOS!$A$2:$A$996,PAGOS!$AE$2:$AE$996,""),""),IFNA(_xlfn.XLOOKUP(A17,PAGOS!$A$2:$A$996,PAGOS!$AH$2:$AH$996,""),""),IFNA(_xlfn.XLOOKUP(A17,PAGOS!$A$2:$A$996,PAGOS!$AK$2:$AK$996,""),"")),IF(abonos>0,abonos,pago)))} -> 950 | E17: =IFERROR(__xludf.DUMMYFUNCTION("IF(A17="""","""",LET(mes,DATE($E$2,MATCH($B$2,'ESTADO CONTABLE'!$A$5:$A$16,0),1),abonos,SUMIFS('ABONOS MENSUALIDADES'!$F$5:$F$500,'ABONOS MENSUALIDADES'!$C$5:$C$500,A17,'ABONOS MENSUALIDADES'!$D$5:$D$500,mes),metodoDirecto,CHOOSE(MATCH($B$2,'ESTADO CONTAB"&"LE'!$A$5:$A$16,0),IF(ISNUMBER(D17),""POR CLASIFICAR"",""""),IFNA(XLOOKUP(A17,PAGOS!$A$2:$A$996,PAGOS!$H$2:$H$996,""""),""""),IFNA(XLOOKUP(A17,PAGOS!$A$2:$A$996,PAGOS!$K$2:$K$996,""""),""""),IFNA(XLOOKUP(A17,PAGOS!$A$2:$A$996,PAGOS!$N$2:$N$996,""""),""""),"&"IFNA(XLOOKUP(A17,PAGOS!$A$2:$A$996,PAGOS!$Q$2:$Q$996,""""),""""),IFNA(XLOOKUP(A17,PAGOS!$A$2:$A$996,PAGOS!$T$2:$T$996,""""),""""),IFNA(XLOOKUP(A17,PAGOS!$A$2:$A$996,PAGOS!$W$2:$W$996,""""),""""),IFNA(XLOOKUP(A17,PAGOS!$A$2:$A$996,PAGOS!$Z$2:$Z$996,""""),"&"""""),IFNA(XLOOKUP(A17,PAGOS!$A$2:$A$996,PAGOS!$AC$2:$AC$996,""""),""""),IFNA(XLOOKUP(A17,PAGOS!$A$2:$A$996,PAGOS!$AF$2:$AF$996,""""),""""),IFNA(XLOOKUP(A17,PAGOS!$A$2:$A$996,PAGOS!$AI$2:$AI$996,""""),""""),IFNA(XLOOKUP(A17,PAGOS!$A$2:$A$996,PAGOS!$AL$2:$"&"AL$996,""""),"""")),IF(abonos>0,IFERROR(TEXTJOIN("" + "",TRUE,UNIQUE(FILTER('ABONOS MENSUALIDADES'!$E$5:$E$500,'ABONOS MENSUALIDADES'!$C$5:$C$500=A17,'ABONOS MENSUALIDADES'!$D$5:$D$500=mes))),""""),metodoDirecto)))"),"TRANSFERENCIA") -> TRANSFERENCIA | F17: {=IF(A17="","",LET(mes,DATE($E$2,MATCH($B$2,'ESTADO CONTABLE'!$A$5:$A$16,0),1),cobrarDesde,IFERROR(INDEX('BASE DE DATOSS'!I:I,ROW()-13),""),pausada,SUMPRODUCT((UPPER(TRIM('PAUSAS MENSUALIDADES'!$A$5:$A$500))=UPPER(TRIM(A17)))*('PAUSAS MENSUALIDADES'!$B$5:$B$500=mes)*(UPPER(TRIM('PAUSAS MENSUALIDADES'!$D$5:$D$500))="APLICAR"))>0,abonoActivo,SUMIFS('ABONOS MENSUALIDADES'!$F$5:$F$500,'ABONOS MENSUALIDADES'!$C$5:$C$500,A17,'ABONOS MENSUALIDADES'!$D$5:$D$500,mes,'ABONOS MENSUALIDADES'!$G$5:$G$500,"<>*CONSOLIDADO EN PAGOS*")>0,esperadaBruta,MAX(IFNA(VLOOKUP(B17,COSTOS!$A$3:$B$13,2,FALSE),0)-150,0),IF(AND(cobrarDesde<>"",mes<cobrarDesde),"AÚN NO INICIA",IF(pausada,"PAUSADA",IF(AND(abonoActivo,COUNTIFS('ABONOS MENSUALIDADES'!$C$5:$C$500,A17,'ABONOS MENSUALIDADES'!$D$5:$D$500,mes,'ABONOS MENSUALIDADES'!$G$5:$G$500,"*MENSUALIDAD LIQUIDADA*")=0),"ABONO",IF(N(D17)>=esperadaBruta,"COBRADA",IF(N(D17)>0,"ABONO","PENDIENTE")))))))} -> COBRADA | G17: {=IF(A17="","",IFERROR(INDEX('BASE DE DATOSS'!I:I,ROW()-13),""))} -> 46023
A18: {=IFERROR(INDEX('BASE DE DATOSS'!A:A,ROW()-13),"")} -> ATENAS KORHEIMI FIGEROA FIGUEROA | B18: {=IF(A18="","",IFERROR(INDEX('BASE DE DATOSS'!C:C,ROW()-13),""))} -> ADULTS 2 | C18: {=IF(A18="","",LET(mes,DATE($E$2,MATCH($B$2,'ESTADO CONTABLE'!$A$5:$A$16,0),1),cobrarDesde,IFERROR(INDEX('BASE DE DATOSS'!I:I,ROW()-13),""),pausada,SUMPRODUCT((UPPER(TRIM('PAUSAS MENSUALIDADES'!$A$5:$A$500))=UPPER(TRIM(A18)))*('PAUSAS MENSUALIDADES'!$B$5:$B$500=mes)*(UPPER(TRIM('PAUSAS MENSUALIDADES'!$D$5:$D$500))="APLICAR"))>0,IF(OR(AND(cobrarDesde<>"",mes<cobrarDesde),pausada),0,MAX(IFNA(VLOOKUP(B18,COSTOS!$A$3:$B$13,2,FALSE),0)-150,0)/1.16)))} -> 818.96552 | D18: {=IF(A18="","",LET(mes,DATE($E$2,MATCH($B$2,'ESTADO CONTABLE'!$A$5:$A$16,0),1),abonos,SUMIFS('ABONOS MENSUALIDADES'!$F$5:$F$500,'ABONOS MENSUALIDADES'!$C$5:$C$500,A18,'ABONOS MENSUALIDADES'!$D$5:$D$500,mes),pago,CHOOSE(MATCH($B$2,'ESTADO CONTABLE'!$A$5:$A$16,0),IFNA(_xlfn.XLOOKUP(A18,PAGOS!$A$2:$A$996,PAGOS!$E$2:$E$996,""),""),IFNA(_xlfn.XLOOKUP(A18,PAGOS!$A$2:$A$996,PAGOS!$G$2:$G$996,""),""),IFNA(_xlfn.XLOOKUP(A18,PAGOS!$A$2:$A$996,PAGOS!$J$2:$J$996,""),""),IFNA(_xlfn.XLOOKUP(A18,PAGOS!$A$2:$A$996,PAGOS!$M$2:$M$996,""),""),IFNA(_xlfn.XLOOKUP(A18,PAGOS!$A$2:$A$996,PAGOS!$P$2:$P$996,""),""),IFNA(_xlfn.XLOOKUP(A18,PAGOS!$A$2:$A$996,PAGOS!$S$2:$S$996,""),""),IFNA(_xlfn.XLOOKUP(A18,PAGOS!$A$2:$A$996,PAGOS!$V$2:$V$996,""),""),IFNA(_xlfn.XLOOKUP(A18,PAGOS!$A$2:$A$996,PAGOS!$Y$2:$Y$996,""),""),IFNA(_xlfn.XLOOKUP(A18,PAGOS!$A$2:$A$996,PAGOS!$AB$2:$AB$996,""),""),IFNA(_xlfn.XLOOKUP(A18,PAGOS!$A$2:$A$996,PAGOS!$AE$2:$AE$996,""),""),IFNA(_xlfn.XLOOKUP(A18,PAGOS!$A$2:$A$996,PAGOS!$AH$2:$AH$996,""),""),IFNA(_xlfn.XLOOKUP(A18,PAGOS!$A$2:$A$996,PAGOS!$AK$2:$AK$996,""),"")),IF(abonos>0,abonos,pago)))} -> 950 | E18: =IFERROR(__xludf.DUMMYFUNCTION("IF(A18="""","""",LET(mes,DATE($E$2,MATCH($B$2,'ESTADO CONTABLE'!$A$5:$A$16,0),1),abonos,SUMIFS('ABONOS MENSUALIDADES'!$F$5:$F$500,'ABONOS MENSUALIDADES'!$C$5:$C$500,A18,'ABONOS MENSUALIDADES'!$D$5:$D$500,mes),metodoDirecto,CHOOSE(MATCH($B$2,'ESTADO CONTAB"&"LE'!$A$5:$A$16,0),IF(ISNUMBER(D18),""POR CLASIFICAR"",""""),IFNA(XLOOKUP(A18,PAGOS!$A$2:$A$996,PAGOS!$H$2:$H$996,""""),""""),IFNA(XLOOKUP(A18,PAGOS!$A$2:$A$996,PAGOS!$K$2:$K$996,""""),""""),IFNA(XLOOKUP(A18,PAGOS!$A$2:$A$996,PAGOS!$N$2:$N$996,""""),""""),"&"IFNA(XLOOKUP(A18,PAGOS!$A$2:$A$996,PAGOS!$Q$2:$Q$996,""""),""""),IFNA(XLOOKUP(A18,PAGOS!$A$2:$A$996,PAGOS!$T$2:$T$996,""""),""""),IFNA(XLOOKUP(A18,PAGOS!$A$2:$A$996,PAGOS!$W$2:$W$996,""""),""""),IFNA(XLOOKUP(A18,PAGOS!$A$2:$A$996,PAGOS!$Z$2:$Z$996,""""),"&"""""),IFNA(XLOOKUP(A18,PAGOS!$A$2:$A$996,PAGOS!$AC$2:$AC$996,""""),""""),IFNA(XLOOKUP(A18,PAGOS!$A$2:$A$996,PAGOS!$AF$2:$AF$996,""""),""""),IFNA(XLOOKUP(A18,PAGOS!$A$2:$A$996,PAGOS!$AI$2:$AI$996,""""),""""),IFNA(XLOOKUP(A18,PAGOS!$A$2:$A$996,PAGOS!$AL$2:$"&"AL$996,""""),"""")),IF(abonos>0,IFERROR(TEXTJOIN("" + "",TRUE,UNIQUE(FILTER('ABONOS MENSUALIDADES'!$E$5:$E$500,'ABONOS MENSUALIDADES'!$C$5:$C$500=A18,'ABONOS MENSUALIDADES'!$D$5:$D$500=mes))),""""),metodoDirecto)))"),"EFECTIVO") -> EFECTIVO | F18: {=IF(A18="","",LET(mes,DATE($E$2,MATCH($B$2,'ESTADO CONTABLE'!$A$5:$A$16,0),1),cobrarDesde,IFERROR(INDEX('BASE DE DATOSS'!I:I,ROW()-13),""),pausada,SUMPRODUCT((UPPER(TRIM('PAUSAS MENSUALIDADES'!$A$5:$A$500))=UPPER(TRIM(A18)))*('PAUSAS MENSUALIDADES'!$B$5:$B$500=mes)*(UPPER(TRIM('PAUSAS MENSUALIDADES'!$D$5:$D$500))="APLICAR"))>0,abonoActivo,SUMIFS('ABONOS MENSUALIDADES'!$F$5:$F$500,'ABONOS MENSUALIDADES'!$C$5:$C$500,A18,'ABONOS MENSUALIDADES'!$D$5:$D$500,mes,'ABONOS MENSUALIDADES'!$G$5:$G$500,"<>*CONSOLIDADO EN PAGOS*")>0,esperadaBruta,MAX(IFNA(VLOOKUP(B18,COSTOS!$A$3:$B$13,2,FALSE),0)-150,0),IF(AND(cobrarDesde<>"",mes<cobrarDesde),"AÚN NO INICIA",IF(pausada,"PAUSADA",IF(AND(abonoActivo,COUNTIFS('ABONOS MENSUALIDADES'!$C$5:$C$500,A18,'ABONOS MENSUALIDADES'!$D$5:$D$500,mes,'ABONOS MENSUALIDADES'!$G$5:$G$500,"*MENSUALIDAD LIQUIDADA*")=0),"ABONO",IF(N(D18)>=esperadaBruta,"COBRADA",IF(N(D18)>0,"ABONO","PENDIENTE")))))))} -> COBRADA | G18: {=IF(A18="","",IFERROR(INDEX('BASE DE DATOSS'!I:I,ROW()-13),""))} -> 46023
A19: {=IFERROR(INDEX('BASE DE DATOSS'!A:A,ROW()-13),"")} -> CARLA VALENTINA GUZMÁN DELGADO | B19: {=IF(A19="","",IFERROR(INDEX('BASE DE DATOSS'!C:C,ROW()-13),""))} -> 5 DIAS KIDS | C19: {=IF(A19="","",LET(mes,DATE($E$2,MATCH($B$2,'ESTADO CONTABLE'!$A$5:$A$16,0),1),cobrarDesde,IFERROR(INDEX('BASE DE DATOSS'!I:I,ROW()-13),""),pausada,SUMPRODUCT((UPPER(TRIM('PAUSAS MENSUALIDADES'!$A$5:$A$500))=UPPER(TRIM(A19)))*('PAUSAS MENSUALIDADES'!$B$5:$B$500=mes)*(UPPER(TRIM('PAUSAS MENSUALIDADES'!$D$5:$D$500))="APLICAR"))>0,IF(OR(AND(cobrarDesde<>"",mes<cobrarDesde),pausada),0,MAX(IFNA(VLOOKUP(B19,COSTOS!$A$3:$B$13,2,FALSE),0)-150,0)/1.16)))} -> 1120.6897 | D19: {=IF(A19="","",LET(mes,DATE($E$2,MATCH($B$2,'ESTADO CONTABLE'!$A$5:$A$16,0),1),abonos,SUMIFS('ABONOS MENSUALIDADES'!$F$5:$F$500,'ABONOS MENSUALIDADES'!$C$5:$C$500,A19,'ABONOS MENSUALIDADES'!$D$5:$D$500,mes),pago,CHOOSE(MATCH($B$2,'ESTADO CONTABLE'!$A$5:$A$16,0),IFNA(_xlfn.XLOOKUP(A19,PAGOS!$A$2:$A$996,PAGOS!$E$2:$E$996,""),""),IFNA(_xlfn.XLOOKUP(A19,PAGOS!$A$2:$A$996,PAGOS!$G$2:$G$996,""),""),IFNA(_xlfn.XLOOKUP(A19,PAGOS!$A$2:$A$996,PAGOS!$J$2:$J$996,""),""),IFNA(_xlfn.XLOOKUP(A19,PAGOS!$A$2:$A$996,PAGOS!$M$2:$M$996,""),""),IFNA(_xlfn.XLOOKUP(A19,PAGOS!$A$2:$A$996,PAGOS!$P$2:$P$996,""),""),IFNA(_xlfn.XLOOKUP(A19,PAGOS!$A$2:$A$996,PAGOS!$S$2:$S$996,""),""),IFNA(_xlfn.XLOOKUP(A19,PAGOS!$A$2:$A$996,PAGOS!$V$2:$V$996,""),""),IFNA(_xlfn.XLOOKUP(A19,PAGOS!$A$2:$A$996,PAGOS!$Y$2:$Y$996,""),""),IFNA(_xlfn.XLOOKUP(A19,PAGOS!$A$2:$A$996,PAGOS!$AB$2:$AB$996,""),""),IFNA(_xlfn.XLOOKUP(A19,PAGOS!$A$2:$A$996,PAGOS!$AE$2:$AE$996,""),""),IFNA(_xlfn.XLOOKUP(A19,PAGOS!$A$2:$A$996,PAGOS!$AH$2:$AH$996,""),""),IFNA(_xlfn.XLOOKUP(A19,PAGOS!$A$2:$A$996,PAGOS!$AK$2:$AK$996,""),"")),IF(abonos>0,abonos,pago)))} -> 1300 | E19: =IFERROR(__xludf.DUMMYFUNCTION("IF(A19="""","""",LET(mes,DATE($E$2,MATCH($B$2,'ESTADO CONTABLE'!$A$5:$A$16,0),1),abonos,SUMIFS('ABONOS MENSUALIDADES'!$F$5:$F$500,'ABONOS MENSUALIDADES'!$C$5:$C$500,A19,'ABONOS MENSUALIDADES'!$D$5:$D$500,mes),metodoDirecto,CHOOSE(MATCH($B$2,'ESTADO CONTAB"&"LE'!$A$5:$A$16,0),IF(ISNUMBER(D19),""POR CLASIFICAR"",""""),IFNA(XLOOKUP(A19,PAGOS!$A$2:$A$996,PAGOS!$H$2:$H$996,""""),""""),IFNA(XLOOKUP(A19,PAGOS!$A$2:$A$996,PAGOS!$K$2:$K$996,""""),""""),IFNA(XLOOKUP(A19,PAGOS!$A$2:$A$996,PAGOS!$N$2:$N$996,""""),""""),"&"IFNA(XLOOKUP(A19,PAGOS!$A$2:$A$996,PAGOS!$Q$2:$Q$996,""""),""""),IFNA(XLOOKUP(A19,PAGOS!$A$2:$A$996,PAGOS!$T$2:$T$996,""""),""""),IFNA(XLOOKUP(A19,PAGOS!$A$2:$A$996,PAGOS!$W$2:$W$996,""""),""""),IFNA(XLOOKUP(A19,PAGOS!$A$2:$A$996,PAGOS!$Z$2:$Z$996,""""),"&"""""),IFNA(XLOOKUP(A19,PAGOS!$A$2:$A$996,PAGOS!$AC$2:$AC$996,""""),""""),IFNA(XLOOKUP(A19,PAGOS!$A$2:$A$996,PAGOS!$AF$2:$AF$996,""""),""""),IFNA(XLOOKUP(A19,PAGOS!$A$2:$A$996,PAGOS!$AI$2:$AI$996,""""),""""),IFNA(XLOOKUP(A19,PAGOS!$A$2:$A$996,PAGOS!$AL$2:$"&"AL$996,""""),"""")),IF(abonos>0,IFERROR(TEXTJOIN("" + "",TRUE,UNIQUE(FILTER('ABONOS MENSUALIDADES'!$E$5:$E$500,'ABONOS MENSUALIDADES'!$C$5:$C$500=A19,'ABONOS MENSUALIDADES'!$D$5:$D$500=mes))),""""),metodoDirecto)))"),"TRANSFERENCIA") -> TRANSFERENCIA | F19: {=IF(A19="","",LET(mes,DATE($E$2,MATCH($B$2,'ESTADO CONTABLE'!$A$5:$A$16,0),1),cobrarDesde,IFERROR(INDEX('BASE DE DATOSS'!I:I,ROW()-13),""),pausada,SUMPRODUCT((UPPER(TRIM('PAUSAS MENSUALIDADES'!$A$5:$A$500))=UPPER(TRIM(A19)))*('PAUSAS MENSUALIDADES'!$B$5:$B$500=mes)*(UPPER(TRIM('PAUSAS MENSUALIDADES'!$D$5:$D$500))="APLICAR"))>0,abonoActivo,SUMIFS('ABONOS MENSUALIDADES'!$F$5:$F$500,'ABONOS MENSUALIDADES'!$C$5:$C$500,A19,'ABONOS MENSUALIDADES'!$D$5:$D$500,mes,'ABONOS MENSUALIDADES'!$G$5:$G$500,"<>*CONSOLIDADO EN PAGOS*")>0,esperadaBruta,MAX(IFNA(VLOOKUP(B19,COSTOS!$A$3:$B$13,2,FALSE),0)-150,0),IF(AND(cobrarDesde<>"",mes<cobrarDesde),"AÚN NO INICIA",IF(pausada,"PAUSADA",IF(AND(abonoActivo,COUNTIFS('ABONOS MENSUALIDADES'!$C$5:$C$500,A19,'ABONOS MENSUALIDADES'!$D$5:$D$500,mes,'ABONOS MENSUALIDADES'!$G$5:$G$500,"*MENSUALIDAD LIQUIDADA*")=0),"ABONO",IF(N(D19)>=esperadaBruta,"COBRADA",IF(N(D19)>0,"ABONO","PENDIENTE")))))))} -> COBRADA | G19: {=IF(A19="","",IFERROR(INDEX('BASE DE DATOSS'!I:I,ROW()-13),""))} -> 46023
A20: {=IFERROR(INDEX('BASE DE DATOSS'!A:A,ROW()-13),"")} -> DANIELA AGUILAR CAZORLA | B20: {=IF(A20="","",IFERROR(INDEX('BASE DE DATOSS'!C:C,ROW()-13),""))} -> ADULTS 2 | C20: {=IF(A20="","",LET(mes,DATE($E$2,MATCH($B$2,'ESTADO CONTABLE'!$A$5:$A$16,0),1),cobrarDesde,IFERROR(INDEX('BASE DE DATOSS'!I:I,ROW()-13),""),pausada,SUMPRODUCT((UPPER(TRIM('PAUSAS MENSUALIDADES'!$A$5:$A$500))=UPPER(TRIM(A20)))*('PAUSAS MENSUALIDADES'!$B$5:$B$500=mes)*(UPPER(TRIM('PAUSAS MENSUALIDADES'!$D$5:$D$500))="APLICAR"))>0,IF(OR(AND(cobrarDesde<>"",mes<cobrarDesde),pausada),0,MAX(IFNA(VLOOKUP(B20,COSTOS!$A$3:$B$13,2,FALSE),0)-150,0)/1.16)))} -> 818.96552 | D20: {=IF(A20="","",LET(mes,DATE($E$2,MATCH($B$2,'ESTADO CONTABLE'!$A$5:$A$16,0),1),abonos,SUMIFS('ABONOS MENSUALIDADES'!$F$5:$F$500,'ABONOS MENSUALIDADES'!$C$5:$C$500,A20,'ABONOS MENSUALIDADES'!$D$5:$D$500,mes),pago,CHOOSE(MATCH($B$2,'ESTADO CONTABLE'!$A$5:$A$16,0),IFNA(_xlfn.XLOOKUP(A20,PAGOS!$A$2:$A$996,PAGOS!$E$2:$E$996,""),""),IFNA(_xlfn.XLOOKUP(A20,PAGOS!$A$2:$A$996,PAGOS!$G$2:$G$996,""),""),IFNA(_xlfn.XLOOKUP(A20,PAGOS!$A$2:$A$996,PAGOS!$J$2:$J$996,""),""),IFNA(_xlfn.XLOOKUP(A20,PAGOS!$A$2:$A$996,PAGOS!$M$2:$M$996,""),""),IFNA(_xlfn.XLOOKUP(A20,PAGOS!$A$2:$A$996,PAGOS!$P$2:$P$996,""),""),IFNA(_xlfn.XLOOKUP(A20,PAGOS!$A$2:$A$996,PAGOS!$S$2:$S$996,""),""),IFNA(_xlfn.XLOOKUP(A20,PAGOS!$A$2:$A$996,PAGOS!$V$2:$V$996,""),""),IFNA(_xlfn.XLOOKUP(A20,PAGOS!$A$2:$A$996,PAGOS!$Y$2:$Y$996,""),""),IFNA(_xlfn.XLOOKUP(A20,PAGOS!$A$2:$A$996,PAGOS!$AB$2:$AB$996,""),""),IFNA(_xlfn.XLOOKUP(A20,PAGOS!$A$2:$A$996,PAGOS!$AE$2:$AE$996,""),""),IFNA(_xlfn.XLOOKUP(A20,PAGOS!$A$2:$A$996,PAGOS!$AH$2:$AH$996,""),""),IFNA(_xlfn.XLOOKUP(A20,PAGOS!$A$2:$A$996,PAGOS!$AK$2:$AK$996,""),"")),IF(abonos>0,abonos,pago)))} | E20: =IFERROR(__xludf.DUMMYFUNCTION("IF(A20="""","""",LET(mes,DATE($E$2,MATCH($B$2,'ESTADO CONTABLE'!$A$5:$A$16,0),1),abonos,SUMIFS('ABONOS MENSUALIDADES'!$F$5:$F$500,'ABONOS MENSUALIDADES'!$C$5:$C$500,A20,'ABONOS MENSUALIDADES'!$D$5:$D$500,mes),metodoDirecto,CHOOSE(MATCH($B$2,'ESTADO CONTAB"&"LE'!$A$5:$A$16,0),IF(ISNUMBER(D20),""POR CLASIFICAR"",""""),IFNA(XLOOKUP(A20,PAGOS!$A$2:$A$996,PAGOS!$H$2:$H$996,""""),""""),IFNA(XLOOKUP(A20,PAGOS!$A$2:$A$996,PAGOS!$K$2:$K$996,""""),""""),IFNA(XLOOKUP(A20,PAGOS!$A$2:$A$996,PAGOS!$N$2:$N$996,""""),""""),"&"IFNA(XLOOKUP(A20,PAGOS!$A$2:$A$996,PAGOS!$Q$2:$Q$996,""""),""""),IFNA(XLOOKUP(A20,PAGOS!$A$2:$A$996,PAGOS!$T$2:$T$996,""""),""""),IFNA(XLOOKUP(A20,PAGOS!$A$2:$A$996,PAGOS!$W$2:$W$996,""""),""""),IFNA(XLOOKUP(A20,PAGOS!$A$2:$A$996,PAGOS!$Z$2:$Z$996,""""),"&"""""),IFNA(XLOOKUP(A20,PAGOS!$A$2:$A$996,PAGOS!$AC$2:$AC$996,""""),""""),IFNA(XLOOKUP(A20,PAGOS!$A$2:$A$996,PAGOS!$AF$2:$AF$996,""""),""""),IFNA(XLOOKUP(A20,PAGOS!$A$2:$A$996,PAGOS!$AI$2:$AI$996,""""),""""),IFNA(XLOOKUP(A20,PAGOS!$A$2:$A$996,PAGOS!$AL$2:$"&"AL$996,""""),"""")),IF(abonos>0,IFERROR(TEXTJOIN("" + "",TRUE,UNIQUE(FILTER('ABONOS MENSUALIDADES'!$E$5:$E$500,'ABONOS MENSUALIDADES'!$C$5:$C$500=A20,'ABONOS MENSUALIDADES'!$D$5:$D$500=mes))),""""),metodoDirecto)))"),"") | F20: {=IF(A20="","",LET(mes,DATE($E$2,MATCH($B$2,'ESTADO CONTABLE'!$A$5:$A$16,0),1),cobrarDesde,IFERROR(INDEX('BASE DE DATOSS'!I:I,ROW()-13),""),pausada,SUMPRODUCT((UPPER(TRIM('PAUSAS MENSUALIDADES'!$A$5:$A$500))=UPPER(TRIM(A20)))*('PAUSAS MENSUALIDADES'!$B$5:$B$500=mes)*(UPPER(TRIM('PAUSAS MENSUALIDADES'!$D$5:$D$500))="APLICAR"))>0,abonoActivo,SUMIFS('ABONOS MENSUALIDADES'!$F$5:$F$500,'ABONOS MENSUALIDADES'!$C$5:$C$500,A20,'ABONOS MENSUALIDADES'!$D$5:$D$500,mes,'ABONOS MENSUALIDADES'!$G$5:$G$500,"<>*CONSOLIDADO EN PAGOS*")>0,esperadaBruta,MAX(IFNA(VLOOKUP(B20,COSTOS!$A$3:$B$13,2,FALSE),0)-150,0),IF(AND(cobrarDesde<>"",mes<cobrarDesde),"AÚN NO INICIA",IF(pausada,"PAUSADA",IF(AND(abonoActivo,COUNTIFS('ABONOS MENSUALIDADES'!$C$5:$C$500,A20,'ABONOS MENSUALIDADES'!$D$5:$D$500,mes,'ABONOS MENSUALIDADES'!$G$5:$G$500,"*MENSUALIDAD LIQUIDADA*")=0),"ABONO",IF(N(D20)>=esperadaBruta,"COBRADA",IF(N(D20)>0,"ABONO","PENDIENTE")))))))} -> PENDIENTE | G20: {=IF(A20="","",IFERROR(INDEX('BASE DE DATOSS'!I:I,ROW()-13),""))} -> 46023
A21: {=IFERROR(INDEX('BASE DE DATOSS'!A:A,ROW()-13),"")} -> DARIANA RODRIGUEZ SANCHEZ | B21: {=IF(A21="","",IFERROR(INDEX('BASE DE DATOSS'!C:C,ROW()-13),""))} -> MATUTINO | C21: {=IF(A21="","",LET(mes,DATE($E$2,MATCH($B$2,'ESTADO CONTABLE'!$A$5:$A$16,0),1),cobrarDesde,IFERROR(INDEX('BASE DE DATOSS'!I:I,ROW()-13),""),pausada,SUMPRODUCT((UPPER(TRIM('PAUSAS MENSUALIDADES'!$A$5:$A$500))=UPPER(TRIM(A21)))*('PAUSAS MENSUALIDADES'!$B$5:$B$500=mes)*(UPPER(TRIM('PAUSAS MENSUALIDADES'!$D$5:$D$500))="APLICAR"))>0,IF(OR(AND(cobrarDesde<>"",mes<cobrarDesde),pausada),0,MAX(IFNA(VLOOKUP(B21,COSTOS!$A$3:$B$13,2,FALSE),0)-150,0)/1.16)))} -> 818.96552 | D21: {=IF(A21="","",LET(mes,DATE($E$2,MATCH($B$2,'ESTADO CONTABLE'!$A$5:$A$16,0),1),abonos,SUMIFS('ABONOS MENSUALIDADES'!$F$5:$F$500,'ABONOS MENSUALIDADES'!$C$5:$C$500,A21,'ABONOS MENSUALIDADES'!$D$5:$D$500,mes),pago,CHOOSE(MATCH($B$2,'ESTADO CONTABLE'!$A$5:$A$16,0),IFNA(_xlfn.XLOOKUP(A21,PAGOS!$A$2:$A$996,PAGOS!$E$2:$E$996,""),""),IFNA(_xlfn.XLOOKUP(A21,PAGOS!$A$2:$A$996,PAGOS!$G$2:$G$996,""),""),IFNA(_xlfn.XLOOKUP(A21,PAGOS!$A$2:$A$996,PAGOS!$J$2:$J$996,""),""),IFNA(_xlfn.XLOOKUP(A21,PAGOS!$A$2:$A$996,PAGOS!$M$2:$M$996,""),""),IFNA(_xlfn.XLOOKUP(A21,PAGOS!$A$2:$A$996,PAGOS!$P$2:$P$996,""),""),IFNA(_xlfn.XLOOKUP(A21,PAGOS!$A$2:$A$996,PAGOS!$S$2:$S$996,""),""),IFNA(_xlfn.XLOOKUP(A21,PAGOS!$A$2:$A$996,PAGOS!$V$2:$V$996,""),""),IFNA(_xlfn.XLOOKUP(A21,PAGOS!$A$2:$A$996,PAGOS!$Y$2:$Y$996,""),""),IFNA(_xlfn.XLOOKUP(A21,PAGOS!$A$2:$A$996,PAGOS!$AB$2:$AB$996,""),""),IFNA(_xlfn.XLOOKUP(A21,PAGOS!$A$2:$A$996,PAGOS!$AE$2:$AE$996,""),""),IFNA(_xlfn.XLOOKUP(A21,PAGOS!$A$2:$A$996,PAGOS!$AH$2:$AH$996,""),""),IFNA(_xlfn.XLOOKUP(A21,PAGOS!$A$2:$A$996,PAGOS!$AK$2:$AK$996,""),"")),IF(abonos>0,abonos,pago)))} -> 950 | E21: =IFERROR(__xludf.DUMMYFUNCTION("IF(A21="""","""",LET(mes,DATE($E$2,MATCH($B$2,'ESTADO CONTABLE'!$A$5:$A$16,0),1),abonos,SUMIFS('ABONOS MENSUALIDADES'!$F$5:$F$500,'ABONOS MENSUALIDADES'!$C$5:$C$500,A21,'ABONOS MENSUALIDADES'!$D$5:$D$500,mes),metodoDirecto,CHOOSE(MATCH($B$2,'ESTADO CONTAB"&"LE'!$A$5:$A$16,0),IF(ISNUMBER(D21),""POR CLASIFICAR"",""""),IFNA(XLOOKUP(A21,PAGOS!$A$2:$A$996,PAGOS!$H$2:$H$996,""""),""""),IFNA(XLOOKUP(A21,PAGOS!$A$2:$A$996,PAGOS!$K$2:$K$996,""""),""""),IFNA(XLOOKUP(A21,PAGOS!$A$2:$A$996,PAGOS!$N$2:$N$996,""""),""""),"&"IFNA(XLOOKUP(A21,PAGOS!$A$2:$A$996,PAGOS!$Q$2:$Q$996,""""),""""),IFNA(XLOOKUP(A21,PAGOS!$A$2:$A$996,PAGOS!$T$2:$T$996,""""),""""),IFNA(XLOOKUP(A21,PAGOS!$A$2:$A$996,PAGOS!$W$2:$W$996,""""),""""),IFNA(XLOOKUP(A21,PAGOS!$A$2:$A$996,PAGOS!$Z$2:$Z$996,""""),"&"""""),IFNA(XLOOKUP(A21,PAGOS!$A$2:$A$996,PAGOS!$AC$2:$AC$996,""""),""""),IFNA(XLOOKUP(A21,PAGOS!$A$2:$A$996,PAGOS!$AF$2:$AF$996,""""),""""),IFNA(XLOOKUP(A21,PAGOS!$A$2:$A$996,PAGOS!$AI$2:$AI$996,""""),""""),IFNA(XLOOKUP(A21,PAGOS!$A$2:$A$996,PAGOS!$AL$2:$"&"AL$996,""""),"""")),IF(abonos>0,IFERROR(TEXTJOIN("" + "",TRUE,UNIQUE(FILTER('ABONOS MENSUALIDADES'!$E$5:$E$500,'ABONOS MENSUALIDADES'!$C$5:$C$500=A21,'ABONOS MENSUALIDADES'!$D$5:$D$500=mes))),""""),metodoDirecto)))"),"TRANSFERENCIA") -> TRANSFERENCIA | F21: {=IF(A21="","",LET(mes,DATE($E$2,MATCH($B$2,'ESTADO CONTABLE'!$A$5:$A$16,0),1),cobrarDesde,IFERROR(INDEX('BASE DE DATOSS'!I:I,ROW()-13),""),pausada,SUMPRODUCT((UPPER(TRIM('PAUSAS MENSUALIDADES'!$A$5:$A$500))=UPPER(TRIM(A21)))*('PAUSAS MENSUALIDADES'!$B$5:$B$500=mes)*(UPPER(TRIM('PAUSAS MENSUALIDADES'!$D$5:$D$500))="APLICAR"))>0,abonoActivo,SUMIFS('ABONOS MENSUALIDADES'!$F$5:$F$500,'ABONOS MENSUALIDADES'!$C$5:$C$500,A21,'ABONOS MENSUALIDADES'!$D$5:$D$500,mes,'ABONOS MENSUALIDADES'!$G$5:$G$500,"<>*CONSOLIDADO EN PAGOS*")>0,esperadaBruta,MAX(IFNA(VLOOKUP(B21,COSTOS!$A$3:$B$13,2,FALSE),0)-150,0),IF(AND(cobrarDesde<>"",mes<cobrarDesde),"AÚN NO INICIA",IF(pausada,"PAUSADA",IF(AND(abonoActivo,COUNTIFS('ABONOS MENSUALIDADES'!$C$5:$C$500,A21,'ABONOS MENSUALIDADES'!$D$5:$D$500,mes,'ABONOS MENSUALIDADES'!$G$5:$G$500,"*MENSUALIDAD LIQUIDADA*")=0),"ABONO",IF(N(D21)>=esperadaBruta,"COBRADA",IF(N(D21)>0,"ABONO","PENDIENTE")))))))} -> COBRADA | G21: {=IF(A21="","",IFERROR(INDEX('BASE DE DATOSS'!I:I,ROW()-13),""))} -> 46023
A22: {=IFERROR(INDEX('BASE DE DATOSS'!A:A,ROW()-13),"")} -> MIA ISABELLA CHAVEZ ARELLANO | B22: {=IF(A22="","",IFERROR(INDEX('BASE DE DATOSS'!C:C,ROW()-13),""))} -> SABATINO | C22: {=IF(A22="","",LET(mes,DATE($E$2,MATCH($B$2,'ESTADO CONTABLE'!$A$5:$A$16,0),1),cobrarDesde,IFERROR(INDEX('BASE DE DATOSS'!I:I,ROW()-13),""),pausada,SUMPRODUCT((UPPER(TRIM('PAUSAS MENSUALIDADES'!$A$5:$A$500))=UPPER(TRIM(A22)))*('PAUSAS MENSUALIDADES'!$B$5:$B$500=mes)*(UPPER(TRIM('PAUSAS MENSUALIDADES'!$D$5:$D$500))="APLICAR"))>0,IF(OR(AND(cobrarDesde<>"",mes<cobrarDesde),pausada),0,MAX(IFNA(VLOOKUP(B22,COSTOS!$A$3:$B$13,2,FALSE),0)-150,0)/1.16)))} -> 474.13793 | D22: {=IF(A22="","",LET(mes,DATE($E$2,MATCH($B$2,'ESTADO CONTABLE'!$A$5:$A$16,0),1),abonos,SUMIFS('ABONOS MENSUALIDADES'!$F$5:$F$500,'ABONOS MENSUALIDADES'!$C$5:$C$500,A22,'ABONOS MENSUALIDADES'!$D$5:$D$500,mes),pago,CHOOSE(MATCH($B$2,'ESTADO CONTABLE'!$A$5:$A$16,0),IFNA(_xlfn.XLOOKUP(A22,PAGOS!$A$2:$A$996,PAGOS!$E$2:$E$996,""),""),IFNA(_xlfn.XLOOKUP(A22,PAGOS!$A$2:$A$996,PAGOS!$G$2:$G$996,""),""),IFNA(_xlfn.XLOOKUP(A22,PAGOS!$A$2:$A$996,PAGOS!$J$2:$J$996,""),""),IFNA(_xlfn.XLOOKUP(A22,PAGOS!$A$2:$A$996,PAGOS!$M$2:$M$996,""),""),IFNA(_xlfn.XLOOKUP(A22,PAGOS!$A$2:$A$996,PAGOS!$P$2:$P$996,""),""),IFNA(_xlfn.XLOOKUP(A22,PAGOS!$A$2:$A$996,PAGOS!$S$2:$S$996,""),""),IFNA(_xlfn.XLOOKUP(A22,PAGOS!$A$2:$A$996,PAGOS!$V$2:$V$996,""),""),IFNA(_xlfn.XLOOKUP(A22,PAGOS!$A$2:$A$996,PAGOS!$Y$2:$Y$996,""),""),IFNA(_xlfn.XLOOKUP(A22,PAGOS!$A$2:$A$996,PAGOS!$AB$2:$AB$996,""),""),IFNA(_xlfn.XLOOKUP(A22,PAGOS!$A$2:$A$996,PAGOS!$AE$2:$AE$996,""),""),IFNA(_xlfn.XLOOKUP(A22,PAGOS!$A$2:$A$996,PAGOS!$AH$2:$AH$996,""),""),IFNA(_xlfn.XLOOKUP(A22,PAGOS!$A$2:$A$996,PAGOS!$AK$2:$AK$996,""),"")),IF(abonos>0,abonos,pago)))} -> 550 | E22: =IFERROR(__xludf.DUMMYFUNCTION("IF(A22="""","""",LET(mes,DATE($E$2,MATCH($B$2,'ESTADO CONTABLE'!$A$5:$A$16,0),1),abonos,SUMIFS('ABONOS MENSUALIDADES'!$F$5:$F$500,'ABONOS MENSUALIDADES'!$C$5:$C$500,A22,'ABONOS MENSUALIDADES'!$D$5:$D$500,mes),metodoDirecto,CHOOSE(MATCH($B$2,'ESTADO CONTAB"&"LE'!$A$5:$A$16,0),IF(ISNUMBER(D22),""POR CLASIFICAR"",""""),IFNA(XLOOKUP(A22,PAGOS!$A$2:$A$996,PAGOS!$H$2:$H$996,""""),""""),IFNA(XLOOKUP(A22,PAGOS!$A$2:$A$996,PAGOS!$K$2:$K$996,""""),""""),IFNA(XLOOKUP(A22,PAGOS!$A$2:$A$996,PAGOS!$N$2:$N$996,""""),""""),"&"IFNA(XLOOKUP(A22,PAGOS!$A$2:$A$996,PAGOS!$Q$2:$Q$996,""""),""""),IFNA(XLOOKUP(A22,PAGOS!$A$2:$A$996,PAGOS!$T$2:$T$996,""""),""""),IFNA(XLOOKUP(A22,PAGOS!$A$2:$A$996,PAGOS!$W$2:$W$996,""""),""""),IFNA(XLOOKUP(A22,PAGOS!$A$2:$A$996,PAGOS!$Z$2:$Z$996,""""),"&"""""),IFNA(XLOOKUP(A22,PAGOS!$A$2:$A$996,PAGOS!$AC$2:$AC$996,""""),""""),IFNA(XLOOKUP(A22,PAGOS!$A$2:$A$996,PAGOS!$AF$2:$AF$996,""""),""""),IFNA(XLOOKUP(A22,PAGOS!$A$2:$A$996,PAGOS!$AI$2:$AI$996,""""),""""),IFNA(XLOOKUP(A22,PAGOS!$A$2:$A$996,PAGOS!$AL$2:$"&"AL$996,""""),"""")),IF(abonos>0,IFERROR(TEXTJOIN("" + "",TRUE,UNIQUE(FILTER('ABONOS MENSUALIDADES'!$E$5:$E$500,'ABONOS MENSUALIDADES'!$C$5:$C$500=A22,'ABONOS MENSUALIDADES'!$D$5:$D$500=mes))),""""),metodoDirecto)))"),"TRANSFERENCIA") -> TRANSFERENCIA | F22: {=IF(A22="","",LET(mes,DATE($E$2,MATCH($B$2,'ESTADO CONTABLE'!$A$5:$A$16,0),1),cobrarDesde,IFERROR(INDEX('BASE DE DATOSS'!I:I,ROW()-13),""),pausada,SUMPRODUCT((UPPER(TRIM('PAUSAS MENSUALIDADES'!$A$5:$A$500))=UPPER(TRIM(A22)))*('PAUSAS MENSUALIDADES'!$B$5:$B$500=mes)*(UPPER(TRIM('PAUSAS MENSUALIDADES'!$D$5:$D$500))="APLICAR"))>0,abonoActivo,SUMIFS('ABONOS MENSUALIDADES'!$F$5:$F$500,'ABONOS MENSUALIDADES'!$C$5:$C$500,A22,'ABONOS MENSUALIDADES'!$D$5:$D$500,mes,'ABONOS MENSUALIDADES'!$G$5:$G$500,"<>*CONSOLIDADO EN PAGOS*")>0,esperadaBruta,MAX(IFNA(VLOOKUP(B22,COSTOS!$A$3:$B$13,2,FALSE),0)-150,0),IF(AND(cobrarDesde<>"",mes<cobrarDesde),"AÚN NO INICIA",IF(pausada,"PAUSADA",IF(AND(abonoActivo,COUNTIFS('ABONOS MENSUALIDADES'!$C$5:$C$500,A22,'ABONOS MENSUALIDADES'!$D$5:$D$500,mes,'ABONOS MENSUALIDADES'!$G$5:$G$500,"*MENSUALIDAD LIQUIDADA*")=0),"ABONO",IF(N(D22)>=esperadaBruta,"COBRADA",IF(N(D22)>0,"ABONO","PENDIENTE")))))))} -> COBRADA | G22: {=IF(A22="","",IFERROR(INDEX('BASE DE DATOSS'!I:I,ROW()-13),""))} -> 46023
A23: {=IFERROR(INDEX('BASE DE DATOSS'!A:A,ROW()-13),"")} -> OXANA VILLALOBOS | B23: {=IF(A23="","",IFERROR(INDEX('BASE DE DATOSS'!C:C,ROW()-13),""))} -> ADULTS 1 | C23: {=IF(A23="","",LET(mes,DATE($E$2,MATCH($B$2,'ESTADO CONTABLE'!$A$5:$A$16,0),1),cobrarDesde,IFERROR(INDEX('BASE DE DATOSS'!I:I,ROW()-13),""),pausada,SUMPRODUCT((UPPER(TRIM('PAUSAS MENSUALIDADES'!$A$5:$A$500))=UPPER(TRIM(A23)))*('PAUSAS MENSUALIDADES'!$B$5:$B$500=mes)*(UPPER(TRIM('PAUSAS MENSUALIDADES'!$D$5:$D$500))="APLICAR"))>0,IF(OR(AND(cobrarDesde<>"",mes<cobrarDesde),pausada),0,MAX(IFNA(VLOOKUP(B23,COSTOS!$A$3:$B$13,2,FALSE),0)-150,0)/1.16)))} -> 991.37931 | D23: {=IF(A23="","",LET(mes,DATE($E$2,MATCH($B$2,'ESTADO CONTABLE'!$A$5:$A$16,0),1),abonos,SUMIFS('ABONOS MENSUALIDADES'!$F$5:$F$500,'ABONOS MENSUALIDADES'!$C$5:$C$500,A23,'ABONOS MENSUALIDADES'!$D$5:$D$500,mes),pago,CHOOSE(MATCH($B$2,'ESTADO CONTABLE'!$A$5:$A$16,0),IFNA(_xlfn.XLOOKUP(A23,PAGOS!$A$2:$A$996,PAGOS!$E$2:$E$996,""),""),IFNA(_xlfn.XLOOKUP(A23,PAGOS!$A$2:$A$996,PAGOS!$G$2:$G$996,""),""),IFNA(_xlfn.XLOOKUP(A23,PAGOS!$A$2:$A$996,PAGOS!$J$2:$J$996,""),""),IFNA(_xlfn.XLOOKUP(A23,PAGOS!$A$2:$A$996,PAGOS!$M$2:$M$996,""),""),IFNA(_xlfn.XLOOKUP(A23,PAGOS!$A$2:$A$996,PAGOS!$P$2:$P$996,""),""),IFNA(_xlfn.XLOOKUP(A23,PAGOS!$A$2:$A$996,PAGOS!$S$2:$S$996,""),""),IFNA(_xlfn.XLOOKUP(A23,PAGOS!$A$2:$A$996,PAGOS!$V$2:$V$996,""),""),IFNA(_xlfn.XLOOKUP(A23,PAGOS!$A$2:$A$996,PAGOS!$Y$2:$Y$996,""),""),IFNA(_xlfn.XLOOKUP(A23,PAGOS!$A$2:$A$996,PAGOS!$AB$2:$AB$996,""),""),IFNA(_xlfn.XLOOKUP(A23,PAGOS!$A$2:$A$996,PAGOS!$AE$2:$AE$996,""),""),IFNA(_xlfn.XLOOKUP(A23,PAGOS!$A$2:$A$996,PAGOS!$AH$2:$AH$996,""),""),IFNA(_xlfn.XLOOKUP(A23,PAGOS!$A$2:$A$996,PAGOS!$AK$2:$AK$996,""),"")),IF(abonos>0,abonos,pago)))} | E23: =IFERROR(__xludf.DUMMYFUNCTION("IF(A23="""","""",LET(mes,DATE($E$2,MATCH($B$2,'ESTADO CONTABLE'!$A$5:$A$16,0),1),abonos,SUMIFS('ABONOS MENSUALIDADES'!$F$5:$F$500,'ABONOS MENSUALIDADES'!$C$5:$C$500,A23,'ABONOS MENSUALIDADES'!$D$5:$D$500,mes),metodoDirecto,CHOOSE(MATCH($B$2,'ESTADO CONTAB"&"LE'!$A$5:$A$16,0),IF(ISNUMBER(D23),""POR CLASIFICAR"",""""),IFNA(XLOOKUP(A23,PAGOS!$A$2:$A$996,PAGOS!$H$2:$H$996,""""),""""),IFNA(XLOOKUP(A23,PAGOS!$A$2:$A$996,PAGOS!$K$2:$K$996,""""),""""),IFNA(XLOOKUP(A23,PAGOS!$A$2:$A$996,PAGOS!$N$2:$N$996,""""),""""),"&"IFNA(XLOOKUP(A23,PAGOS!$A$2:$A$996,PAGOS!$Q$2:$Q$996,""""),""""),IFNA(XLOOKUP(A23,PAGOS!$A$2:$A$996,PAGOS!$T$2:$T$996,""""),""""),IFNA(XLOOKUP(A23,PAGOS!$A$2:$A$996,PAGOS!$W$2:$W$996,""""),""""),IFNA(XLOOKUP(A23,PAGOS!$A$2:$A$996,PAGOS!$Z$2:$Z$996,""""),"&"""""),IFNA(XLOOKUP(A23,PAGOS!$A$2:$A$996,PAGOS!$AC$2:$AC$996,""""),""""),IFNA(XLOOKUP(A23,PAGOS!$A$2:$A$996,PAGOS!$AF$2:$AF$996,""""),""""),IFNA(XLOOKUP(A23,PAGOS!$A$2:$A$996,PAGOS!$AI$2:$AI$996,""""),""""),IFNA(XLOOKUP(A23,PAGOS!$A$2:$A$996,PAGOS!$AL$2:$"&"AL$996,""""),"""")),IF(abonos>0,IFERROR(TEXTJOIN("" + "",TRUE,UNIQUE(FILTER('ABONOS MENSUALIDADES'!$E$5:$E$500,'ABONOS MENSUALIDADES'!$C$5:$C$500=A23,'ABONOS MENSUALIDADES'!$D$5:$D$500=mes))),""""),metodoDirecto)))"),"") | F23: {=IF(A23="","",LET(mes,DATE($E$2,MATCH($B$2,'ESTADO CONTABLE'!$A$5:$A$16,0),1),cobrarDesde,IFERROR(INDEX('BASE DE DATOSS'!I:I,ROW()-13),""),pausada,SUMPRODUCT((UPPER(TRIM('PAUSAS MENSUALIDADES'!$A$5:$A$500))=UPPER(TRIM(A23)))*('PAUSAS MENSUALIDADES'!$B$5:$B$500=mes)*(UPPER(TRIM('PAUSAS MENSUALIDADES'!$D$5:$D$500))="APLICAR"))>0,abonoActivo,SUMIFS('ABONOS MENSUALIDADES'!$F$5:$F$500,'ABONOS MENSUALIDADES'!$C$5:$C$500,A23,'ABONOS MENSUALIDADES'!$D$5:$D$500,mes,'ABONOS MENSUALIDADES'!$G$5:$G$500,"<>*CONSOLIDADO EN PAGOS*")>0,esperadaBruta,MAX(IFNA(VLOOKUP(B23,COSTOS!$A$3:$B$13,2,FALSE),0)-150,0),IF(AND(cobrarDesde<>"",mes<cobrarDesde),"AÚN NO INICIA",IF(pausada,"PAUSADA",IF(AND(abonoActivo,COUNTIFS('ABONOS MENSUALIDADES'!$C$5:$C$500,A23,'ABONOS MENSUALIDADES'!$D$5:$D$500,mes,'ABONOS MENSUALIDADES'!$G$5:$G$500,"*MENSUALIDAD LIQUIDADA*")=0),"ABONO",IF(N(D23)>=esperadaBruta,"COBRADA",IF(N(D23)>0,"ABONO","PENDIENTE")))))))} -> PENDIENTE | G23: {=IF(A23="","",IFERROR(INDEX('BASE DE DATOSS'!I:I,ROW()-13),""))} -> 46023
A24: {=IFERROR(INDEX('BASE DE DATOSS'!A:A,ROW()-13),"")} -> REGINA GUADALUPE RODRIGUEZ CHAVEZ | B24: {=IF(A24="","",IFERROR(INDEX('BASE DE DATOSS'!C:C,ROW()-13),""))} -> JR 2 | C24: {=IF(A24="","",LET(mes,DATE($E$2,MATCH($B$2,'ESTADO CONTABLE'!$A$5:$A$16,0),1),cobrarDesde,IFERROR(INDEX('BASE DE DATOSS'!I:I,ROW()-13),""),pausada,SUMPRODUCT((UPPER(TRIM('PAUSAS MENSUALIDADES'!$A$5:$A$500))=UPPER(TRIM(A24)))*('PAUSAS MENSUALIDADES'!$B$5:$B$500=mes)*(UPPER(TRIM('PAUSAS MENSUALIDADES'!$D$5:$D$500))="APLICAR"))>0,IF(OR(AND(cobrarDesde<>"",mes<cobrarDesde),pausada),0,MAX(IFNA(VLOOKUP(B24,COSTOS!$A$3:$B$13,2,FALSE),0)-150,0)/1.16)))} -> 689.65517 | D24: {=IF(A24="","",LET(mes,DATE($E$2,MATCH($B$2,'ESTADO CONTABLE'!$A$5:$A$16,0),1),abonos,SUMIFS('ABONOS MENSUALIDADES'!$F$5:$F$500,'ABONOS MENSUALIDADES'!$C$5:$C$500,A24,'ABONOS MENSUALIDADES'!$D$5:$D$500,mes),pago,CHOOSE(MATCH($B$2,'ESTADO CONTABLE'!$A$5:$A$16,0),IFNA(_xlfn.XLOOKUP(A24,PAGOS!$A$2:$A$996,PAGOS!$E$2:$E$996,""),""),IFNA(_xlfn.XLOOKUP(A24,PAGOS!$A$2:$A$996,PAGOS!$G$2:$G$996,""),""),IFNA(_xlfn.XLOOKUP(A24,PAGOS!$A$2:$A$996,PAGOS!$J$2:$J$996,""),""),IFNA(_xlfn.XLOOKUP(A24,PAGOS!$A$2:$A$996,PAGOS!$M$2:$M$996,""),""),IFNA(_xlfn.XLOOKUP(A24,PAGOS!$A$2:$A$996,PAGOS!$P$2:$P$996,""),""),IFNA(_xlfn.XLOOKUP(A24,PAGOS!$A$2:$A$996,PAGOS!$S$2:$S$996,""),""),IFNA(_xlfn.XLOOKUP(A24,PAGOS!$A$2:$A$996,PAGOS!$V$2:$V$996,""),""),IFNA(_xlfn.XLOOKUP(A24,PAGOS!$A$2:$A$996,PAGOS!$Y$2:$Y$996,""),""),IFNA(_xlfn.XLOOKUP(A24,PAGOS!$A$2:$A$996,PAGOS!$AB$2:$AB$996,""),""),IFNA(_xlfn.XLOOKUP(A24,PAGOS!$A$2:$A$996,PAGOS!$AE$2:$AE$996,""),""),IFNA(_xlfn.XLOOKUP(A24,PAGOS!$A$2:$A$996,PAGOS!$AH$2:$AH$996,""),""),IFNA(_xlfn.XLOOKUP(A24,PAGOS!$A$2:$A$996,PAGOS!$AK$2:$AK$996,""),"")),IF(abonos>0,abonos,pago)))} -> 800 | E24: =IFERROR(__xludf.DUMMYFUNCTION("IF(A24="""","""",LET(mes,DATE($E$2,MATCH($B$2,'ESTADO CONTABLE'!$A$5:$A$16,0),1),abonos,SUMIFS('ABONOS MENSUALIDADES'!$F$5:$F$500,'ABONOS MENSUALIDADES'!$C$5:$C$500,A24,'ABONOS MENSUALIDADES'!$D$5:$D$500,mes),metodoDirecto,CHOOSE(MATCH($B$2,'ESTADO CONTAB"&"LE'!$A$5:$A$16,0),IF(ISNUMBER(D24),""POR CLASIFICAR"",""""),IFNA(XLOOKUP(A24,PAGOS!$A$2:$A$996,PAGOS!$H$2:$H$996,""""),""""),IFNA(XLOOKUP(A24,PAGOS!$A$2:$A$996,PAGOS!$K$2:$K$996,""""),""""),IFNA(XLOOKUP(A24,PAGOS!$A$2:$A$996,PAGOS!$N$2:$N$996,""""),""""),"&"IFNA(XLOOKUP(A24,PAGOS!$A$2:$A$996,PAGOS!$Q$2:$Q$996,""""),""""),IFNA(XLOOKUP(A24,PAGOS!$A$2:$A$996,PAGOS!$T$2:$T$996,""""),""""),IFNA(XLOOKUP(A24,PAGOS!$A$2:$A$996,PAGOS!$W$2:$W$996,""""),""""),IFNA(XLOOKUP(A24,PAGOS!$A$2:$A$996,PAGOS!$Z$2:$Z$996,""""),"&"""""),IFNA(XLOOKUP(A24,PAGOS!$A$2:$A$996,PAGOS!$AC$2:$AC$996,""""),""""),IFNA(XLOOKUP(A24,PAGOS!$A$2:$A$996,PAGOS!$AF$2:$AF$996,""""),""""),IFNA(XLOOKUP(A24,PAGOS!$A$2:$A$996,PAGOS!$AI$2:$AI$996,""""),""""),IFNA(XLOOKUP(A24,PAGOS!$A$2:$A$996,PAGOS!$AL$2:$"&"AL$996,""""),"""")),IF(abonos>0,IFERROR(TEXTJOIN("" + "",TRUE,UNIQUE(FILTER('ABONOS MENSUALIDADES'!$E$5:$E$500,'ABONOS MENSUALIDADES'!$C$5:$C$500=A24,'ABONOS MENSUALIDADES'!$D$5:$D$500=mes))),""""),metodoDirecto)))"),"EFECTIVO") -> EFECTIVO | F24: {=IF(A24="","",LET(mes,DATE($E$2,MATCH($B$2,'ESTADO CONTABLE'!$A$5:$A$16,0),1),cobrarDesde,IFERROR(INDEX('BASE DE DATOSS'!I:I,ROW()-13),""),pausada,SUMPRODUCT((UPPER(TRIM('PAUSAS MENSUALIDADES'!$A$5:$A$500))=UPPER(TRIM(A24)))*('PAUSAS MENSUALIDADES'!$B$5:$B$500=mes)*(UPPER(TRIM('PAUSAS MENSUALIDADES'!$D$5:$D$500))="APLICAR"))>0,abonoActivo,SUMIFS('ABONOS MENSUALIDADES'!$F$5:$F$500,'ABONOS MENSUALIDADES'!$C$5:$C$500,A24,'ABONOS MENSUALIDADES'!$D$5:$D$500,mes,'ABONOS MENSUALIDADES'!$G$5:$G$500,"<>*CONSOLIDADO EN PAGOS*")>0,esperadaBruta,MAX(IFNA(VLOOKUP(B24,COSTOS!$A$3:$B$13,2,FALSE),0)-150,0),IF(AND(cobrarDesde<>"",mes<cobrarDesde),"AÚN NO INICIA",IF(pausada,"PAUSADA",IF(AND(abonoActivo,COUNTIFS('ABONOS MENSUALIDADES'!$C$5:$C$500,A24,'ABONOS MENSUALIDADES'!$D$5:$D$500,mes,'ABONOS MENSUALIDADES'!$G$5:$G$500,"*MENSUALIDAD LIQUIDADA*")=0),"ABONO",IF(N(D24)>=esperadaBruta,"COBRADA",IF(N(D24)>0,"ABONO","PENDIENTE")))))))} -> COBRADA | G24: {=IF(A24="","",IFERROR(INDEX('BASE DE DATOSS'!I:I,ROW()-13),""))} -> 46023
A25: {=IFERROR(INDEX('BASE DE DATOSS'!A:A,ROW()-13),"")} -> REGINA J CHAVEZ ALCARAZ | B25: {=IF(A25="","",LET(mes,DATE($E$2,MATCH($B$2,'ESTADO CONTABLE'!$A$5:$A$16,0),1),grupoActual,IFERROR(INDEX('BASE DE DATOSS'!C:C,ROW()-13),""),IF(AND(UPPER(TRIM(A25))="REGINA J CHAVEZ ALCARAZ",mes<DATE(2026,10,1)),"ADULTS 1",grupoActual)))} -> ADULTS 2 | C25: {=IF(A25="","",LET(mes,DATE($E$2,MATCH($B$2,'ESTADO CONTABLE'!$A$5:$A$16,0),1),cobrarDesde,IFERROR(INDEX('BASE DE DATOSS'!I:I,ROW()-13),""),pausada,SUMPRODUCT((UPPER(TRIM('PAUSAS MENSUALIDADES'!$A$5:$A$500))=UPPER(TRIM(A25)))*('PAUSAS MENSUALIDADES'!$B$5:$B$500=mes)*(UPPER(TRIM('PAUSAS MENSUALIDADES'!$D$5:$D$500))="APLICAR"))>0,IF(OR(AND(cobrarDesde<>"",mes<cobrarDesde),pausada),0,MAX(IFNA(VLOOKUP(B25,COSTOS!$A$3:$B$13,2,FALSE),0)-150,0)/1.16)))} -> 818.96552 | D25: {=IF(A25="","",LET(mes,DATE($E$2,MATCH($B$2,'ESTADO CONTABLE'!$A$5:$A$16,0),1),abonos,SUMIFS('ABONOS MENSUALIDADES'!$F$5:$F$500,'ABONOS MENSUALIDADES'!$C$5:$C$500,A25,'ABONOS MENSUALIDADES'!$D$5:$D$500,mes),pago,CHOOSE(MATCH($B$2,'ESTADO CONTABLE'!$A$5:$A$16,0),IFNA(_xlfn.XLOOKUP(A25,PAGOS!$A$2:$A$996,PAGOS!$E$2:$E$996,""),""),IFNA(_xlfn.XLOOKUP(A25,PAGOS!$A$2:$A$996,PAGOS!$G$2:$G$996,""),""),IFNA(_xlfn.XLOOKUP(A25,PAGOS!$A$2:$A$996,PAGOS!$J$2:$J$996,""),""),IFNA(_xlfn.XLOOKUP(A25,PAGOS!$A$2:$A$996,PAGOS!$M$2:$M$996,""),""),IFNA(_xlfn.XLOOKUP(A25,PAGOS!$A$2:$A$996,PAGOS!$P$2:$P$996,""),""),IFNA(_xlfn.XLOOKUP(A25,PAGOS!$A$2:$A$996,PAGOS!$S$2:$S$996,""),""),IFNA(_xlfn.XLOOKUP(A25,PAGOS!$A$2:$A$996,PAGOS!$V$2:$V$996,""),""),IFNA(_xlfn.XLOOKUP(A25,PAGOS!$A$2:$A$996,PAGOS!$Y$2:$Y$996,""),""),IFNA(_xlfn.XLOOKUP(A25,PAGOS!$A$2:$A$996,PAGOS!$AB$2:$AB$996,""),""),IFNA(_xlfn.XLOOKUP(A25,PAGOS!$A$2:$A$996,PAGOS!$AE$2:$AE$996,""),""),IFNA(_xlfn.XLOOKUP(A25,PAGOS!$A$2:$A$996,PAGOS!$AH$2:$AH$996,""),""),IFNA(_xlfn.XLOOKUP(A25,PAGOS!$A$2:$A$996,PAGOS!$AK$2:$AK$996,""),"")),IF(abonos>0,abonos,pago)))} -> 950 | E25: =IFERROR(__xludf.DUMMYFUNCTION("IF(A25="""","""",LET(mes,DATE($E$2,MATCH($B$2,'ESTADO CONTABLE'!$A$5:$A$16,0),1),abonos,SUMIFS('ABONOS MENSUALIDADES'!$F$5:$F$500,'ABONOS MENSUALIDADES'!$C$5:$C$500,A25,'ABONOS MENSUALIDADES'!$D$5:$D$500,mes),metodoDirecto,CHOOSE(MATCH($B$2,'ESTADO CONTAB"&"LE'!$A$5:$A$16,0),IF(ISNUMBER(D25),""POR CLASIFICAR"",""""),IFNA(XLOOKUP(A25,PAGOS!$A$2:$A$996,PAGOS!$H$2:$H$996,""""),""""),IFNA(XLOOKUP(A25,PAGOS!$A$2:$A$996,PAGOS!$K$2:$K$996,""""),""""),IFNA(XLOOKUP(A25,PAGOS!$A$2:$A$996,PAGOS!$N$2:$N$996,""""),""""),"&"IFNA(XLOOKUP(A25,PAGOS!$A$2:$A$996,PAGOS!$Q$2:$Q$996,""""),""""),IFNA(XLOOKUP(A25,PAGOS!$A$2:$A$996,PAGOS!$T$2:$T$996,""""),""""),IFNA(XLOOKUP(A25,PAGOS!$A$2:$A$996,PAGOS!$W$2:$W$996,""""),""""),IFNA(XLOOKUP(A25,PAGOS!$A$2:$A$996,PAGOS!$Z$2:$Z$996,""""),"&"""""),IFNA(XLOOKUP(A25,PAGOS!$A$2:$A$996,PAGOS!$AC$2:$AC$996,""""),""""),IFNA(XLOOKUP(A25,PAGOS!$A$2:$A$996,PAGOS!$AF$2:$AF$996,""""),""""),IFNA(XLOOKUP(A25,PAGOS!$A$2:$A$996,PAGOS!$AI$2:$AI$996,""""),""""),IFNA(XLOOKUP(A25,PAGOS!$A$2:$A$996,PAGOS!$AL$2:$"&"AL$996,""""),"""")),IF(abonos>0,IFERROR(TEXTJOIN("" + "",TRUE,UNIQUE(FILTER('ABONOS MENSUALIDADES'!$E$5:$E$500,'ABONOS MENSUALIDADES'!$C$5:$C$500=A25,'ABONOS MENSUALIDADES'!$D$5:$D$500=mes))),""""),metodoDirecto)))"),"TRANSFERENCIA") -> TRANSFERENCIA | F25: {=IF(A25="","",LET(mes,DATE($E$2,MATCH($B$2,'ESTADO CONTABLE'!$A$5:$A$16,0),1),cobrarDesde,IFERROR(INDEX('BASE DE DATOSS'!I:I,ROW()-13),""),pausada,SUMPRODUCT((UPPER(TRIM('PAUSAS MENSUALIDADES'!$A$5:$A$500))=UPPER(TRIM(A25)))*('PAUSAS MENSUALIDADES'!$B$5:$B$500=mes)*(UPPER(TRIM('PAUSAS MENSUALIDADES'!$D$5:$D$500))="APLICAR"))>0,abonoActivo,SUMIFS('ABONOS MENSUALIDADES'!$F$5:$F$500,'ABONOS MENSUALIDADES'!$C$5:$C$500,A25,'ABONOS MENSUALIDADES'!$D$5:$D$500,mes,'ABONOS MENSUALIDADES'!$G$5:$G$500,"<>*CONSOLIDADO EN PAGOS*")>0,esperadaBruta,MAX(IFNA(VLOOKUP(B25,COSTOS!$A$3:$B$13,2,FALSE),0)-150,0),IF(AND(cobrarDesde<>"",mes<cobrarDesde),"AÚN NO INICIA",IF(pausada,"PAUSADA",IF(AND(abonoActivo,COUNTIFS('ABONOS MENSUALIDADES'!$C$5:$C$500,A25,'ABONOS MENSUALIDADES'!$D$5:$D$500,mes,'ABONOS MENSUALIDADES'!$G$5:$G$500,"*MENSUALIDAD LIQUIDADA*")=0),"ABONO",IF(N(D25)>=esperadaBruta,"COBRADA",IF(N(D25)>0,"ABONO","PENDIENTE")))))))} -> COBRADA | G25: {=IF(A25="","",IFERROR(INDEX('BASE DE DATOSS'!I:I,ROW()-13),""))} -> 46023
A26: {=IFERROR(INDEX('BASE DE DATOSS'!A:A,ROW()-13),"")} -> SOFIA HERMAYONIE AVILA GUERRERO | B26: {=IF(A26="","",LET(mes,DATE($E$2,MATCH($B$2,'ESTADO CONTABLE'!$A$5:$A$16,0),1),grupoActual,IFERROR(INDEX('BASE DE DATOSS'!C:C,ROW()-13),""),IF(AND(UPPER(TRIM(A26))="SOFIA HERMAYONIE AVILA GUERRERO",mes<DATE(2026,10,1)),"JR 2",grupoActual)))} -> ADULTS 1 | C26: {=IF(A26="","",LET(mes,DATE($E$2,MATCH($B$2,'ESTADO CONTABLE'!$A$5:$A$16,0),1),cobrarDesde,IFERROR(INDEX('BASE DE DATOSS'!I:I,ROW()-13),""),pausada,SUMPRODUCT((UPPER(TRIM('PAUSAS MENSUALIDADES'!$A$5:$A$500))=UPPER(TRIM(A26)))*('PAUSAS MENSUALIDADES'!$B$5:$B$500=mes)*(UPPER(TRIM('PAUSAS MENSUALIDADES'!$D$5:$D$500))="APLICAR"))>0,IF(OR(AND(cobrarDesde<>"",mes<cobrarDesde),pausada),0,MAX(IFNA(VLOOKUP(B26,COSTOS!$A$3:$B$13,2,FALSE),0)-150,0)/1.16)))} -> 991.37931 | D26: {=IF(A26="","",LET(mes,DATE($E$2,MATCH($B$2,'ESTADO CONTABLE'!$A$5:$A$16,0),1),abonos,SUMIFS('ABONOS MENSUALIDADES'!$F$5:$F$500,'ABONOS MENSUALIDADES'!$C$5:$C$500,A26,'ABONOS MENSUALIDADES'!$D$5:$D$500,mes),pago,CHOOSE(MATCH($B$2,'ESTADO CONTABLE'!$A$5:$A$16,0),IFNA(_xlfn.XLOOKUP(A26,PAGOS!$A$2:$A$996,PAGOS!$E$2:$E$996,""),""),IFNA(_xlfn.XLOOKUP(A26,PAGOS!$A$2:$A$996,PAGOS!$G$2:$G$996,""),""),IFNA(_xlfn.XLOOKUP(A26,PAGOS!$A$2:$A$996,PAGOS!$J$2:$J$996,""),""),IFNA(_xlfn.XLOOKUP(A26,PAGOS!$A$2:$A$996,PAGOS!$M$2:$M$996,""),""),IFNA(_xlfn.XLOOKUP(A26,PAGOS!$A$2:$A$996,PAGOS!$P$2:$P$996,""),""),IFNA(_xlfn.XLOOKUP(A26,PAGOS!$A$2:$A$996,PAGOS!$S$2:$S$996,""),""),IFNA(_xlfn.XLOOKUP(A26,PAGOS!$A$2:$A$996,PAGOS!$V$2:$V$996,""),""),IFNA(_xlfn.XLOOKUP(A26,PAGOS!$A$2:$A$996,PAGOS!$Y$2:$Y$996,""),""),IFNA(_xlfn.XLOOKUP(A26,PAGOS!$A$2:$A$996,PAGOS!$AB$2:$AB$996,""),""),IFNA(_xlfn.XLOOKUP(A26,PAGOS!$A$2:$A$996,PAGOS!$AE$2:$AE$996,""),""),IFNA(_xlfn.XLOOKUP(A26,PAGOS!$A$2:$A$996,PAGOS!$AH$2:$AH$996,""),""),IFNA(_xlfn.XLOOKUP(A26,PAGOS!$A$2:$A$996,PAGOS!$AK$2:$AK$996,""),"")),IF(abonos>0,abonos,pago)))} | E26: =IFERROR(__xludf.DUMMYFUNCTION("IF(A26="""","""",LET(mes,DATE($E$2,MATCH($B$2,'ESTADO CONTABLE'!$A$5:$A$16,0),1),abonos,SUMIFS('ABONOS MENSUALIDADES'!$F$5:$F$500,'ABONOS MENSUALIDADES'!$C$5:$C$500,A26,'ABONOS MENSUALIDADES'!$D$5:$D$500,mes),metodoDirecto,CHOOSE(MATCH($B$2,'ESTADO CONTAB"&"LE'!$A$5:$A$16,0),IF(ISNUMBER(D26),""POR CLASIFICAR"",""""),IFNA(XLOOKUP(A26,PAGOS!$A$2:$A$996,PAGOS!$H$2:$H$996,""""),""""),IFNA(XLOOKUP(A26,PAGOS!$A$2:$A$996,PAGOS!$K$2:$K$996,""""),""""),IFNA(XLOOKUP(A26,PAGOS!$A$2:$A$996,PAGOS!$N$2:$N$996,""""),""""),"&"IFNA(XLOOKUP(A26,PAGOS!$A$2:$A$996,PAGOS!$Q$2:$Q$996,""""),""""),IFNA(XLOOKUP(A26,PAGOS!$A$2:$A$996,PAGOS!$T$2:$T$996,""""),""""),IFNA(XLOOKUP(A26,PAGOS!$A$2:$A$996,PAGOS!$W$2:$W$996,""""),""""),IFNA(XLOOKUP(A26,PAGOS!$A$2:$A$996,PAGOS!$Z$2:$Z$996,""""),"&"""""),IFNA(XLOOKUP(A26,PAGOS!$A$2:$A$996,PAGOS!$AC$2:$AC$996,""""),""""),IFNA(XLOOKUP(A26,PAGOS!$A$2:$A$996,PAGOS!$AF$2:$AF$996,""""),""""),IFNA(XLOOKUP(A26,PAGOS!$A$2:$A$996,PAGOS!$AI$2:$AI$996,""""),""""),IFNA(XLOOKUP(A26,PAGOS!$A$2:$A$996,PAGOS!$AL$2:$"&"AL$996,""""),"""")),IF(abonos>0,IFERROR(TEXTJOIN("" + "",TRUE,UNIQUE(FILTER('ABONOS MENSUALIDADES'!$E$5:$E$500,'ABONOS MENSUALIDADES'!$C$5:$C$500=A26,'ABONOS MENSUALIDADES'!$D$5:$D$500=mes))),""""),metodoDirecto)))"),"") | F26: {=IF(A26="","",LET(mes,DATE($E$2,MATCH($B$2,'ESTADO CONTABLE'!$A$5:$A$16,0),1),cobrarDesde,IFERROR(INDEX('BASE DE DATOSS'!I:I,ROW()-13),""),pausada,SUMPRODUCT((UPPER(TRIM('PAUSAS MENSUALIDADES'!$A$5:$A$500))=UPPER(TRIM(A26)))*('PAUSAS MENSUALIDADES'!$B$5:$B$500=mes)*(UPPER(TRIM('PAUSAS MENSUALIDADES'!$D$5:$D$500))="APLICAR"))>0,abonoActivo,SUMIFS('ABONOS MENSUALIDADES'!$F$5:$F$500,'ABONOS MENSUALIDADES'!$C$5:$C$500,A26,'ABONOS MENSUALIDADES'!$D$5:$D$500,mes,'ABONOS MENSUALIDADES'!$G$5:$G$500,"<>*CONSOLIDADO EN PAGOS*")>0,esperadaBruta,MAX(IFNA(VLOOKUP(B26,COSTOS!$A$3:$B$13,2,FALSE),0)-150,0),IF(AND(cobrarDesde<>"",mes<cobrarDesde),"AÚN NO INICIA",IF(pausada,"PAUSADA",IF(AND(abonoActivo,COUNTIFS('ABONOS MENSUALIDADES'!$C$5:$C$500,A26,'ABONOS MENSUALIDADES'!$D$5:$D$500,mes,'ABONOS MENSUALIDADES'!$G$5:$G$500,"*MENSUALIDAD LIQUIDADA*")=0),"ABONO",IF(N(D26)>=esperadaBruta,"COBRADA",IF(N(D26)>0,"ABONO","PENDIENTE")))))))} -> PENDIENTE | G26: {=IF(A26="","",IFERROR(INDEX('BASE DE DATOSS'!I:I,ROW()-13),""))} -> 46023
A27: {=IFERROR(INDEX('BASE DE DATOSS'!A:A,ROW()-13),"")} -> VALENTINA GÓMEZ NEGRETE | B27: {=IF(A27="","",IFERROR(INDEX('BASE DE DATOSS'!C:C,ROW()-13),""))} -> JR 2 | C27: {=IF(A27="","",LET(mes,DATE($E$2,MATCH($B$2,'ESTADO CONTABLE'!$A$5:$A$16,0),1),cobrarDesde,IFERROR(INDEX('BASE DE DATOSS'!I:I,ROW()-13),""),pausada,SUMPRODUCT((UPPER(TRIM('PAUSAS MENSUALIDADES'!$A$5:$A$500))=UPPER(TRIM(A27)))*('PAUSAS MENSUALIDADES'!$B$5:$B$500=mes)*(UPPER(TRIM('PAUSAS MENSUALIDADES'!$D$5:$D$500))="APLICAR"))>0,IF(OR(AND(cobrarDesde<>"",mes<cobrarDesde),pausada),0,MAX(IFNA(VLOOKUP(B27,COSTOS!$A$3:$B$13,2,FALSE),0)-150,0)/1.16)))} -> 689.65517 | D27: {=IF(A27="","",LET(mes,DATE($E$2,MATCH($B$2,'ESTADO CONTABLE'!$A$5:$A$16,0),1),abonos,SUMIFS('ABONOS MENSUALIDADES'!$F$5:$F$500,'ABONOS MENSUALIDADES'!$C$5:$C$500,A27,'ABONOS MENSUALIDADES'!$D$5:$D$500,mes),pago,CHOOSE(MATCH($B$2,'ESTADO CONTABLE'!$A$5:$A$16,0),IFNA(_xlfn.XLOOKUP(A27,PAGOS!$A$2:$A$996,PAGOS!$E$2:$E$996,""),""),IFNA(_xlfn.XLOOKUP(A27,PAGOS!$A$2:$A$996,PAGOS!$G$2:$G$996,""),""),IFNA(_xlfn.XLOOKUP(A27,PAGOS!$A$2:$A$996,PAGOS!$J$2:$J$996,""),""),IFNA(_xlfn.XLOOKUP(A27,PAGOS!$A$2:$A$996,PAGOS!$M$2:$M$996,""),""),IFNA(_xlfn.XLOOKUP(A27,PAGOS!$A$2:$A$996,PAGOS!$P$2:$P$996,""),""),IFNA(_xlfn.XLOOKUP(A27,PAGOS!$A$2:$A$996,PAGOS!$S$2:$S$996,""),""),IFNA(_xlfn.XLOOKUP(A27,PAGOS!$A$2:$A$996,PAGOS!$V$2:$V$996,""),""),IFNA(_xlfn.XLOOKUP(A27,PAGOS!$A$2:$A$996,PAGOS!$Y$2:$Y$996,""),""),IFNA(_xlfn.XLOOKUP(A27,PAGOS!$A$2:$A$996,PAGOS!$AB$2:$AB$996,""),""),IFNA(_xlfn.XLOOKUP(A27,PAGOS!$A$2:$A$996,PAGOS!$AE$2:$AE$996,""),""),IFNA(_xlfn.XLOOKUP(A27,PAGOS!$A$2:$A$996,PAGOS!$AH$2:$AH$996,""),""),IFNA(_xlfn.XLOOKUP(A27,PAGOS!$A$2:$A$996,PAGOS!$AK$2:$AK$996,""),"")),IF(abonos>0,abonos,pago)))} -> 800 | E27: =IFERROR(__xludf.DUMMYFUNCTION("IF(A27="""","""",LET(mes,DATE($E$2,MATCH($B$2,'ESTADO CONTABLE'!$A$5:$A$16,0),1),abonos,SUMIFS('ABONOS MENSUALIDADES'!$F$5:$F$500,'ABONOS MENSUALIDADES'!$C$5:$C$500,A27,'ABONOS MENSUALIDADES'!$D$5:$D$500,mes),metodoDirecto,CHOOSE(MATCH($B$2,'ESTADO CONTAB"&"LE'!$A$5:$A$16,0),IF(ISNUMBER(D27),""POR CLASIFICAR"",""""),IFNA(XLOOKUP(A27,PAGOS!$A$2:$A$996,PAGOS!$H$2:$H$996,""""),""""),IFNA(XLOOKUP(A27,PAGOS!$A$2:$A$996,PAGOS!$K$2:$K$996,""""),""""),IFNA(XLOOKUP(A27,PAGOS!$A$2:$A$996,PAGOS!$N$2:$N$996,""""),""""),"&"IFNA(XLOOKUP(A27,PAGOS!$A$2:$A$996,PAGOS!$Q$2:$Q$996,""""),""""),IFNA(XLOOKUP(A27,PAGOS!$A$2:$A$996,PAGOS!$T$2:$T$996,""""),""""),IFNA(XLOOKUP(A27,PAGOS!$A$2:$A$996,PAGOS!$W$2:$W$996,""""),""""),IFNA(XLOOKUP(A27,PAGOS!$A$2:$A$996,PAGOS!$Z$2:$Z$996,""""),"&"""""),IFNA(XLOOKUP(A27,PAGOS!$A$2:$A$996,PAGOS!$AC$2:$AC$996,""""),""""),IFNA(XLOOKUP(A27,PAGOS!$A$2:$A$996,PAGOS!$AF$2:$AF$996,""""),""""),IFNA(XLOOKUP(A27,PAGOS!$A$2:$A$996,PAGOS!$AI$2:$AI$996,""""),""""),IFNA(XLOOKUP(A27,PAGOS!$A$2:$A$996,PAGOS!$AL$2:$"&"AL$996,""""),"""")),IF(abonos>0,IFERROR(TEXTJOIN("" + "",TRUE,UNIQUE(FILTER('ABONOS MENSUALIDADES'!$E$5:$E$500,'ABONOS MENSUALIDADES'!$C$5:$C$500=A27,'ABONOS MENSUALIDADES'!$D$5:$D$500=mes))),""""),metodoDirecto)))"),"EFECTIVO") -> EFECTIVO | F27: {=IF(A27="","",LET(mes,DATE($E$2,MATCH($B$2,'ESTADO CONTABLE'!$A$5:$A$16,0),1),cobrarDesde,IFERROR(INDEX('BASE DE DATOSS'!I:I,ROW()-13),""),pausada,SUMPRODUCT((UPPER(TRIM('PAUSAS MENSUALIDADES'!$A$5:$A$500))=UPPER(TRIM(A27)))*('PAUSAS MENSUALIDADES'!$B$5:$B$500=mes)*(UPPER(TRIM('PAUSAS MENSUALIDADES'!$D$5:$D$500))="APLICAR"))>0,abonoActivo,SUMIFS('ABONOS MENSUALIDADES'!$F$5:$F$500,'ABONOS MENSUALIDADES'!$C$5:$C$500,A27,'ABONOS MENSUALIDADES'!$D$5:$D$500,mes,'ABONOS MENSUALIDADES'!$G$5:$G$500,"<>*CONSOLIDADO EN PAGOS*")>0,esperadaBruta,MAX(IFNA(VLOOKUP(B27,COSTOS!$A$3:$B$13,2,FALSE),0)-150,0),IF(AND(cobrarDesde<>"",mes<cobrarDesde),"AÚN NO INICIA",IF(pausada,"PAUSADA",IF(AND(abonoActivo,COUNTIFS('ABONOS MENSUALIDADES'!$C$5:$C$500,A27,'ABONOS MENSUALIDADES'!$D$5:$D$500,mes,'ABONOS MENSUALIDADES'!$G$5:$G$500,"*MENSUALIDAD LIQUIDADA*")=0),"ABONO",IF(N(D27)>=esperadaBruta,"COBRADA",IF(N(D27)>0,"ABONO","PENDIENTE")))))))} -> COBRADA | G27: {=IF(A27="","",IFERROR(INDEX('BASE DE DATOSS'!I:I,ROW()-13),""))} -> 46023
A28: {=IFERROR(INDEX('BASE DE DATOSS'!A:A,ROW()-13),"")} -> DANNA VALERIA DE LA CRUZ HEREDIA | B28: {=IF(A28="","",IFERROR(INDEX('BASE DE DATOSS'!C:C,ROW()-13),""))} -> KIDS 3 | C28: {=IF(A28="","",LET(mes,DATE($E$2,MATCH($B$2,'ESTADO CONTABLE'!$A$5:$A$16,0),1),cobrarDesde,IFERROR(INDEX('BASE DE DATOSS'!I:I,ROW()-13),""),pausada,SUMPRODUCT((UPPER(TRIM('PAUSAS MENSUALIDADES'!$A$5:$A$500))=UPPER(TRIM(A28)))*('PAUSAS MENSUALIDADES'!$B$5:$B$500=mes)*(UPPER(TRIM('PAUSAS MENSUALIDADES'!$D$5:$D$500))="APLICAR"))>0,IF(OR(AND(cobrarDesde<>"",mes<cobrarDesde),pausada),0,MAX(IFNA(VLOOKUP(B28,COSTOS!$A$3:$B$13,2,FALSE),0)-150,0)/1.16)))} -> 689.65517 | D28: {=IF(A28="","",LET(mes,DATE($E$2,MATCH($B$2,'ESTADO CONTABLE'!$A$5:$A$16,0),1),abonos,SUMIFS('ABONOS MENSUALIDADES'!$F$5:$F$500,'ABONOS MENSUALIDADES'!$C$5:$C$500,A28,'ABONOS MENSUALIDADES'!$D$5:$D$500,mes),pago,CHOOSE(MATCH($B$2,'ESTADO CONTABLE'!$A$5:$A$16,0),IFNA(_xlfn.XLOOKUP(A28,PAGOS!$A$2:$A$996,PAGOS!$E$2:$E$996,""),""),IFNA(_xlfn.XLOOKUP(A28,PAGOS!$A$2:$A$996,PAGOS!$G$2:$G$996,""),""),IFNA(_xlfn.XLOOKUP(A28,PAGOS!$A$2:$A$996,PAGOS!$J$2:$J$996,""),""),IFNA(_xlfn.XLOOKUP(A28,PAGOS!$A$2:$A$996,PAGOS!$M$2:$M$996,""),""),IFNA(_xlfn.XLOOKUP(A28,PAGOS!$A$2:$A$996,PAGOS!$P$2:$P$996,""),""),IFNA(_xlfn.XLOOKUP(A28,PAGOS!$A$2:$A$996,PAGOS!$S$2:$S$996,""),""),IFNA(_xlfn.XLOOKUP(A28,PAGOS!$A$2:$A$996,PAGOS!$V$2:$V$996,""),""),IFNA(_xlfn.XLOOKUP(A28,PAGOS!$A$2:$A$996,PAGOS!$Y$2:$Y$996,""),""),IFNA(_xlfn.XLOOKUP(A28,PAGOS!$A$2:$A$996,PAGOS!$AB$2:$AB$996,""),""),IFNA(_xlfn.XLOOKUP(A28,PAGOS!$A$2:$A$996,PAGOS!$AE$2:$AE$996,""),""),IFNA(_xlfn.XLOOKUP(A28,PAGOS!$A$2:$A$996,PAGOS!$AH$2:$AH$996,""),""),IFNA(_xlfn.XLOOKUP(A28,PAGOS!$A$2:$A$996,PAGOS!$AK$2:$AK$996,""),"")),IF(abonos>0,abonos,pago)))} -> 800 | E28: =IFERROR(__xludf.DUMMYFUNCTION("IF(A28="""","""",LET(mes,DATE($E$2,MATCH($B$2,'ESTADO CONTABLE'!$A$5:$A$16,0),1),abonos,SUMIFS('ABONOS MENSUALIDADES'!$F$5:$F$500,'ABONOS MENSUALIDADES'!$C$5:$C$500,A28,'ABONOS MENSUALIDADES'!$D$5:$D$500,mes),metodoDirecto,CHOOSE(MATCH($B$2,'ESTADO CONTAB"&"LE'!$A$5:$A$16,0),IF(ISNUMBER(D28),""POR CLASIFICAR"",""""),IFNA(XLOOKUP(A28,PAGOS!$A$2:$A$996,PAGOS!$H$2:$H$996,""""),""""),IFNA(XLOOKUP(A28,PAGOS!$A$2:$A$996,PAGOS!$K$2:$K$996,""""),""""),IFNA(XLOOKUP(A28,PAGOS!$A$2:$A$996,PAGOS!$N$2:$N$996,""""),""""),"&"IFNA(XLOOKUP(A28,PAGOS!$A$2:$A$996,PAGOS!$Q$2:$Q$996,""""),""""),IFNA(XLOOKUP(A28,PAGOS!$A$2:$A$996,PAGOS!$T$2:$T$996,""""),""""),IFNA(XLOOKUP(A28,PAGOS!$A$2:$A$996,PAGOS!$W$2:$W$996,""""),""""),IFNA(XLOOKUP(A28,PAGOS!$A$2:$A$996,PAGOS!$Z$2:$Z$996,""""),"&"""""),IFNA(XLOOKUP(A28,PAGOS!$A$2:$A$996,PAGOS!$AC$2:$AC$996,""""),""""),IFNA(XLOOKUP(A28,PAGOS!$A$2:$A$996,PAGOS!$AF$2:$AF$996,""""),""""),IFNA(XLOOKUP(A28,PAGOS!$A$2:$A$996,PAGOS!$AI$2:$AI$996,""""),""""),IFNA(XLOOKUP(A28,PAGOS!$A$2:$A$996,PAGOS!$AL$2:$"&"AL$996,""""),"""")),IF(abonos>0,IFERROR(TEXTJOIN("" + "",TRUE,UNIQUE(FILTER('ABONOS MENSUALIDADES'!$E$5:$E$500,'ABONOS MENSUALIDADES'!$C$5:$C$500=A28,'ABONOS MENSUALIDADES'!$D$5:$D$500=mes))),""""),metodoDirecto)))"),"EFECTIVO") -> EFECTIVO | F28: {=IF(A28="","",LET(mes,DATE($E$2,MATCH($B$2,'ESTADO CONTABLE'!$A$5:$A$16,0),1),cobrarDesde,IFERROR(INDEX('BASE DE DATOSS'!I:I,ROW()-13),""),pausada,SUMPRODUCT((UPPER(TRIM('PAUSAS MENSUALIDADES'!$A$5:$A$500))=UPPER(TRIM(A28)))*('PAUSAS MENSUALIDADES'!$B$5:$B$500=mes)*(UPPER(TRIM('PAUSAS MENSUALIDADES'!$D$5:$D$500))="APLICAR"))>0,abonoActivo,SUMIFS('ABONOS MENSUALIDADES'!$F$5:$F$500,'ABONOS MENSUALIDADES'!$C$5:$C$500,A28,'ABONOS MENSUALIDADES'!$D$5:$D$500,mes,'ABONOS MENSUALIDADES'!$G$5:$G$500,"<>*CONSOLIDADO EN PAGOS*")>0,esperadaBruta,MAX(IFNA(VLOOKUP(B28,COSTOS!$A$3:$B$13,2,FALSE),0)-150,0),IF(AND(cobrarDesde<>"",mes<cobrarDesde),"AÚN NO INICIA",IF(pausada,"PAUSADA",IF(AND(abonoActivo,COUNTIFS('ABONOS MENSUALIDADES'!$C$5:$C$500,A28,'ABONOS MENSUALIDADES'!$D$5:$D$500,mes,'ABONOS MENSUALIDADES'!$G$5:$G$500,"*MENSUALIDAD LIQUIDADA*")=0),"ABONO",IF(N(D28)>=esperadaBruta,"COBRADA",IF(N(D28)>0,"ABONO","PENDIENTE")))))))} -> COBRADA | G28: {=IF(A28="","",IFERROR(INDEX('BASE DE DATOSS'!I:I,ROW()-13),""))} -> 46023
